<robot name = "robot">
    <link name="Torso">
        <inertial>
            <origin xyz="0 0 1.475" rpy="0 0 0"/>
            <mass value="1" />
            <inertia ixx="100" ixy="0" ixz="0" iyy="100" iyz="0" izz="100" />
        </inertial>
        <visual>
            <origin xyz="0 0 1.475" rpy="0 0 0"/>
            <geometry>
                <box size="3 2.5 1.25" />
            </geometry>
            <material name="Cyan">
            <color rgba="0.1 0.1 0.4 1.0"/>
            </material>
        </visual>
        <collision>
            <origin xyz="0 0 1.475" rpy="0 0 0"/>
            <geometry>
                <box size="3 2.5 1.25" />
            </geometry>
        </collision>
    </link>
    <joint name="Torso_LegBackLeft" type="revolute">
       <parent link="Torso"/>
       <child  link="LegBackLeft"/>
       <origin rpy="0 0 0" xyz="-1.3125 -1.0625 1.1" />
     <axis xyz="1 1 0"/>
       <limit effort="0.0" lower="-3.14159" upper="3.14159" velocity="0.0"/>
    </joint>
    <link name="LegBackLeft">
        <inertial>
            <origin xyz="0 0 -0.425" rpy="0 0 0"/>
            <mass value="1" />
            <inertia ixx="100" ixy="0" ixz="0" iyy="100" iyz="0" izz="100" />
        </inertial>
        <visual>
            <origin xyz="0 0 -0.425" rpy="0 0 0"/>
            <geometry>
                <box size="0.625 0.625 0.85" />
            </geometry>
            <material name="Cyan">
            <color rgba="0.537 0.886 0.615 1.0"/>
            </material>
        </visual>
        <collision>
            <origin xyz="0 0 -0.425" rpy="0 0 0"/>
            <geometry>
                <box size="0.625 0.625 0.85" />
            </geometry>
        </collision>
    </link>
    <joint name="Torso_LegBackRight" type="revolute">
       <parent link="Torso"/>
       <child  link="LegBackRight"/>
       <origin rpy="0 0 0" xyz="-1.3125 1.0625 1.1" />
     <axis xyz="1 1 0"/>
       <limit effort="0.0" lower="-3.14159" upper="3.14159" velocity="0.0"/>
    </joint>
    <link name="LegBackRight">
        <inertial>
            <origin xyz="0 0 -0.425" rpy="0 0 0"/>
            <mass value="1" />
            <inertia ixx="100" ixy="0" ixz="0" iyy="100" iyz="0" izz="100" />
        </inertial>
        <visual>
            <origin xyz="0 0 -0.425" rpy="0 0 0"/>
            <geometry>
                <box size="0.625 0.625 0.85" />
            </geometry>
            <material name="Cyan">
            <color rgba="0.537 0.886 0.615 1.0"/>
            </material>
        </visual>
        <collision>
            <origin xyz="0 0 -0.425" rpy="0 0 0"/>
            <geometry>
                <box size="0.625 0.625 0.85" />
            </geometry>
        </collision>
    </link>
    <joint name="Torso_LegFrontLeft" type="revolute">
       <parent link="Torso"/>
       <child  link="LegFrontLeft"/>
       <origin rpy="0 0 0" xyz="1.3125 -1.0625 1.1" />
     <axis xyz="1 1 0"/>
       <limit effort="0.0" lower="-3.14159" upper="3.14159" velocity="0.0"/>
    </joint>
    <link name="LegFrontLeft">
        <inertial>
            <origin xyz="0 0 -0.425" rpy="0 0 0"/>
            <mass value="1" />
            <inertia ixx="100" ixy="0" ixz="0" iyy="100" iyz="0" izz="100" />
        </inertial>
        <visual>
            <origin xyz="0 0 -0.425" rpy="0 0 0"/>
            <geometry>
                <box size="0.625 0.625 0.85" />
            </geometry>
            <material name="Cyan">
            <color rgba="0.537 0.886 0.615 1.0"/>
            </material>
        </visual>
        <collision>
            <origin xyz="0 0 -0.425" rpy="0 0 0"/>
            <geometry>
                <box size="0.625 0.625 0.85" />
            </geometry>
        </collision>
    </link>
    <joint name="Torso_LegFrontRight" type="revolute">
       <parent link="Torso"/>
       <child  link="LegFrontRight"/>
       <origin rpy="0 0 0" xyz="1.3125 1.0625 1.1" />
     <axis xyz="1 1 0"/>
       <limit effort="0.0" lower="-3.14159" upper="3.14159" velocity="0.0"/>
    </joint>
    <link name="LegFrontRight">
        <inertial>
            <origin xyz="0 0 -0.425" rpy="0 0 0"/>
            <mass value="1" />
            <inertia ixx="100" ixy="0" ixz="0" iyy="100" iyz="0" izz="100" />
        </inertial>
        <visual>
            <origin xyz="0 0 -0.425" rpy="0 0 0"/>
            <geometry>
                <box size="0.625 0.625 0.85" />
            </geometry>
            <material name="Cyan">
            <color rgba="0.537 0.886 0.615 1.0"/>
            </material>
        </visual>
        <collision>
            <origin xyz="0 0 -0.425" rpy="0 0 0"/>
            <geometry>
                <box size="0.625 0.625 0.85" />
            </geometry>
        </collision>
    </link>
    <joint name="LegBackLeft_FootBackLeft" type="revolute">
       <parent link="LegBackLeft"/>
       <child  link="FootBackLeft"/>
       <origin rpy="0 0 0" xyz="0 0 -0.85" />
     <axis xyz="1 1 0"/>
       <limit effort="0.0" lower="-3.14159" upper="3.14159" velocity="0.0"/>
    </joint>
    <link name="FootBackLeft">
        <inertial>
            <origin xyz="0 0 -0.125" rpy="0 0 0"/>
            <mass value="1" />
            <inertia ixx="100" ixy="0" ixz="0" iyy="100" iyz="0" izz="100" />
        </inertial>
        <visual>
            <origin xyz="0 0 -0.125" rpy="0 0 0"/>
            <geometry>
                <box size="0.7 0.7 0.25" />
            </geometry>
            <material name="Cyan">
            <color rgba="0.537 0.886 0.615 1.0"/>
            </material>
        </visual>
        <collision>
            <origin xyz="0 0 -0.125" rpy="0 0 0"/>
            <geometry>
                <box size="0.7 0.7 0.25" />
            </geometry>
        </collision>
    </link>
    <joint name="LegBackRight_FootBackRight" type="revolute">
       <parent link="LegBackRight"/>
       <child  link="FootBackRight"/>
       <origin rpy="0 0 0" xyz="0 0 -0.85" />
     <axis xyz="0 1 0"/>
       <limit effort="0.0" lower="-3.14159" upper="3.14159" velocity="0.0"/>
    </joint>
    <link name="FootBackRight">
        <inertial>
            <origin xyz="0 0 -0.125" rpy="0 0 0"/>
            <mass value="1" />
            <inertia ixx="100" ixy="0" ixz="0" iyy="100" iyz="0" izz="100" />
        </inertial>
        <visual>
            <origin xyz="0 0 -0.125" rpy="0 0 0"/>
            <geometry>
                <box size="0.7 0.7 0.25" />
            </geometry>
            <material name="Cyan">
            <color rgba="0.537 0.886 0.615 1.0"/>
            </material>
        </visual>
        <collision>
            <origin xyz="0 0 -0.125" rpy="0 0 0"/>
            <geometry>
                <box size="0.7 0.7 0.25" />
            </geometry>
        </collision>
    </link>
    <joint name="LegFrontLeft_FootFrontLeft" type="revolute">
       <parent link="LegFrontLeft"/>
       <child  link="FootFrontLeft"/>
       <origin rpy="0 0 0" xyz="0 0 -0.85" />
     <axis xyz="0 1 0"/>
       <limit effort="0.0" lower="-3.14159" upper="3.14159" velocity="0.0"/>
    </joint>
    <link name="FootFrontLeft">
        <inertial>
            <origin xyz="0 0 -0.125" rpy="0 0 0"/>
            <mass value="1" />
            <inertia ixx="100" ixy="0" ixz="0" iyy="100" iyz="0" izz="100" />
        </inertial>
        <visual>
            <origin xyz="0 0 -0.125" rpy="0 0 0"/>
            <geometry>
                <box size="0.7 0.7 0.25" />
            </geometry>
            <material name="Cyan">
            <color rgba="0.537 0.886 0.615 1.0"/>
            </material>
        </visual>
        <collision>
            <origin xyz="0 0 -0.125" rpy="0 0 0"/>
            <geometry>
                <box size="0.7 0.7 0.25" />
            </geometry>
        </collision>
    </link>
    <joint name="LegFrontRight_FootFrontRight" type="revolute">
       <parent link="LegFrontRight"/>
       <child  link="FootFrontRight"/>
       <origin rpy="0 0 0" xyz="0 0 -0.85" />
     <axis xyz="0 1 0"/>
       <limit effort="0.0" lower="-3.14159" upper="3.14159" velocity="0.0"/>
    </joint>
    <link name="FootFrontRight">
        <inertial>
            <origin xyz="0 0 -0.125" rpy="0 0 0"/>
            <mass value="1" />
            <inertia ixx="100" ixy="0" ixz="0" iyy="100" iyz="0" izz="100" />
        </inertial>
        <visual>
            <origin xyz="0 0 -0.125" rpy="0 0 0"/>
            <geometry>
                <box size="0.7 0.7 0.25" />
            </geometry>
            <material name="Cyan">
            <color rgba="0.537 0.886 0.615 1.0"/>
            </material>
        </visual>
        <collision>
            <origin xyz="0 0 -0.125" rpy="0 0 0"/>
            <geometry>
                <box size="0.7 0.7 0.25" />
            </geometry>
        </collision>
    </link>
    <joint name="Torso_Head" type="revolute">
       <parent link="Torso"/>
       <child  link="Head"/>
       <origin rpy="0 0 0" xyz="1.25 0 1.675" />
     <axis xyz="0 1 0"/>
       <limit effort="0.0" lower="-3.14159" upper="3.14159" velocity="0.0"/>
    </joint>
    <link name="Head">
        <inertial>
            <origin xyz="0.35 0 0.6" rpy="0 0 0"/>
            <mass value="1" />
            <inertia ixx="100" ixy="0" ixz="0" iyy="100" iyz="0" izz="100" />
        </inertial>
        <visual>
            <origin xyz="0.35 0 0.6" rpy="0 0 0"/>
            <geometry>
                <box size="1 1 1" />
            </geometry>
            <material name="Cyan">
            <color rgba="0.537 0.886 0.615 1.0"/>
            </material>
        </visual>
        <collision>
            <origin xyz="0.35 0 0.6" rpy="0 0 0"/>
            <geometry>
                <box size="1 1 1" />
            </geometry>
        </collision>
    </link>
    <joint name="Torso_Shell1" type="revolute">
       <parent link="Torso"/>
       <child  link="Shell1"/>
       <origin rpy="0 0 0" xyz="0 0 2.1" />
     <axis xyz="0 1 0"/>
       <limit effort="0.0" lower="-3.14159" upper="3.14159" velocity="0.0"/>
    </joint>
    <link name="Shell1">
        <inertial>
            <origin xyz="0 0 0.05" rpy="0 0 0"/>
            <mass value="1" />
            <inertia ixx="100" ixy="0" ixz="0" iyy="100" iyz="0" izz="100" />
        </inertial>
        <visual>
            <origin xyz="0 0 0.05" rpy="0 0 0"/>
            <geometry>
                <box size="2.75 2.25 0.1" />
            </geometry>
            <material name="Cyan">
            <color rgba="0.537 0.886 0.615 1.0"/>
            </material>
        </visual>
        <collision>
            <origin xyz="0 0 0.05" rpy="0 0 0"/>
            <geometry>
                <box size="2.75 2.25 0.1" />
            </geometry>
        </collision>
    </link>
    <joint name="Shell1_Shell2" type="revolute">
       <parent link="Shell1"/>
       <child  link="Shell2"/>
       <origin rpy="0 0 0" xyz="0 0 0.1" />
     <axis xyz="0 1 0"/>
       <limit effort="0.0" lower="-3.14159" upper="3.14159" velocity="0.0"/>
    </joint>
    <link name="Shell2">
        <inertial>
            <origin xyz="0 0 0.05" rpy="0 0 0"/>
            <mass value="1" />
            <inertia ixx="100" ixy="0" ixz="0" iyy="100" iyz="0" izz="100" />
        </inertial>
        <visual>
            <origin xyz="0 0 0.05" rpy="0 0 0"/>
            <geometry>
                <box size="2.5 2 0.1" />
            </geometry>
            <material name="Cyan">
            <color rgba="0.537 0.886 0.615 1.0"/>
            </material>
        </visual>
        <collision>
            <origin xyz="0 0 0.05" rpy="0 0 0"/>
            <geometry>
                <box size="2.5 2 0.1" />
            </geometry>
        </collision>
    </link>
</robot>