<robot name = "robot">
    <link name="Link0">
        <inertial>
            <origin xyz="0 0 2.292481967982776" rpy="0 0 0"/>
            <mass value="1.0" />
            <inertia ixx="100" ixy="0" ixz="0" iyy="100" iyz="0" izz="100" />
        </inertial>
        <visual>
            <origin xyz="0 0 2.292481967982776" rpy="0 0 0"/>
            <geometry>
                <box size="0.8389766661989506 0.453963554633605 0.5849639359655523" />
            </geometry>
            <material name="Green">
            <color rgba="0.164 0.776 0.478 1.0"/>
            </material>
        </visual>
        <collision>
            <origin xyz="0 0 2.292481967982776" rpy="0 0 0"/>
            <geometry>
                <box size="0.8389766661989506 0.453963554633605 0.5849639359655523" />
            </geometry>
        </collision>
    </link>
    <link name="Link1">
        <inertial>
            <origin xyz="0.2733035071790194 0.0 0.0" rpy="0 0 0"/>
            <mass value="1.0" />
            <inertia ixx="100" ixy="0" ixz="0" iyy="100" iyz="0" izz="100" />
        </inertial>
        <visual>
            <origin xyz="0.2733035071790194 0.0 0.0" rpy="0 0 0"/>
            <geometry>
                <box size="0.5466070143580388 0.36668672788930207 0.6498980663623024" />
            </geometry>
            <material name="Green">
            <color rgba="0.164 0.776 0.478 1.0"/>
            </material>
        </visual>
        <collision>
            <origin xyz="0.2733035071790194 0.0 0.0" rpy="0 0 0"/>
            <geometry>
                <box size="0.5466070143580388 0.36668672788930207 0.6498980663623024" />
            </geometry>
        </collision>
    </link>
    <link name="Link2">
        <inertial>
            <origin xyz="0.0 0.3329734312469218 0.0" rpy="0 0 0"/>
            <mass value="1.0" />
            <inertia ixx="100" ixy="0" ixz="0" iyy="100" iyz="0" izz="100" />
        </inertial>
        <visual>
            <origin xyz="0.0 0.3329734312469218 0.0" rpy="0 0 0"/>
            <geometry>
                <box size="0.9935729025379922 0.6659468624938436 0.9843125510342683" />
            </geometry>
            <material name="Blue">
            <color rgba="0.164 0.776 0.95 1.0"/>
            </material>
        </visual>
        <collision>
            <origin xyz="0.0 0.3329734312469218 0.0" rpy="0 0 0"/>
            <geometry>
                <box size="0.9935729025379922 0.6659468624938436 0.9843125510342683" />
            </geometry>
        </collision>
    </link>
    <link name="Link3">
        <inertial>
            <origin xyz="0.36802994126815036 0.0 0.0" rpy="0 0 0"/>
            <mass value="1.0" />
            <inertia ixx="100" ixy="0" ixz="0" iyy="100" iyz="0" izz="100" />
        </inertial>
        <visual>
            <origin xyz="0.36802994126815036 0.0 0.0" rpy="0 0 0"/>
            <geometry>
                <box size="0.7360598825363007 0.9369171567035506 0.427675742585836" />
            </geometry>
            <material name="Green">
            <color rgba="0.164 0.776 0.478 1.0"/>
            </material>
        </visual>
        <collision>
            <origin xyz="0.36802994126815036 0.0 0.0" rpy="0 0 0"/>
            <geometry>
                <box size="0.7360598825363007 0.9369171567035506 0.427675742585836" />
            </geometry>
        </collision>
    </link>
    <link name="Link4">
        <inertial>
            <origin xyz="-0.48988876966203454 0.0 0.0" rpy="0 0 0"/>
            <mass value="1.0" />
            <inertia ixx="100" ixy="0" ixz="0" iyy="100" iyz="0" izz="100" />
        </inertial>
        <visual>
            <origin xyz="-0.48988876966203454 0.0 0.0" rpy="0 0 0"/>
            <geometry>
                <box size="0.9797775393240691 0.7669786156421208 0.5601050050664675" />
            </geometry>
            <material name="Green">
            <color rgba="0.164 0.776 0.478 1.0"/>
            </material>
        </visual>
        <collision>
            <origin xyz="-0.48988876966203454 0.0 0.0" rpy="0 0 0"/>
            <geometry>
                <box size="0.9797775393240691 0.7669786156421208 0.5601050050664675" />
            </geometry>
        </collision>
    </link>
    <link name="Link5">
        <inertial>
            <origin xyz="0.0 0.0 -0.3871397556762428" rpy="0 0 0"/>
            <mass value="1.0" />
            <inertia ixx="100" ixy="0" ixz="0" iyy="100" iyz="0" izz="100" />
        </inertial>
        <visual>
            <origin xyz="0.0 0.0 -0.3871397556762428" rpy="0 0 0"/>
            <geometry>
                <box size="0.6386485994909773 0.27824613273239385 0.7742795113524856" />
            </geometry>
            <material name="Blue">
            <color rgba="0.164 0.776 0.95 1.0"/>
            </material>
        </visual>
        <collision>
            <origin xyz="0.0 0.0 -0.3871397556762428" rpy="0 0 0"/>
            <geometry>
                <box size="0.6386485994909773 0.27824613273239385 0.7742795113524856" />
            </geometry>
        </collision>
    </link>
    <link name="Link6">
        <inertial>
            <origin xyz="0.0 0.0 -0.33232307524012566" rpy="0 0 0"/>
            <mass value="1.0" />
            <inertia ixx="100" ixy="0" ixz="0" iyy="100" iyz="0" izz="100" />
        </inertial>
        <visual>
            <origin xyz="0.0 0.0 -0.33232307524012566" rpy="0 0 0"/>
            <geometry>
                <box size="0.5017104787624549 0.9663532908415569 0.6646461504802513" />
            </geometry>
            <material name="Green">
            <color rgba="0.164 0.776 0.478 1.0"/>
            </material>
        </visual>
        <collision>
            <origin xyz="0.0 0.0 -0.33232307524012566" rpy="0 0 0"/>
            <geometry>
                <box size="0.5017104787624549 0.9663532908415569 0.6646461504802513" />
            </geometry>
        </collision>
    </link>
    <link name="Link7">
        <inertial>
            <origin xyz="0.0 -0.42762697875667777 0.0" rpy="0 0 0"/>
            <mass value="1.0" />
            <inertia ixx="100" ixy="0" ixz="0" iyy="100" iyz="0" izz="100" />
        </inertial>
        <visual>
            <origin xyz="0.0 -0.42762697875667777 0.0" rpy="0 0 0"/>
            <geometry>
                <box size="0.6403260977219472 0.8552539575133555 0.4525715172574362" />
            </geometry>
            <material name="Blue">
            <color rgba="0.164 0.776 0.95 1.0"/>
            </material>
        </visual>
        <collision>
            <origin xyz="0.0 -0.42762697875667777 0.0" rpy="0 0 0"/>
            <geometry>
                <box size="0.6403260977219472 0.8552539575133555 0.4525715172574362" />
            </geometry>
        </collision>
    </link>
    <link name="Link8">
        <inertial>
            <origin xyz="0.0 0.13428331750888356 0.0" rpy="0 0 0"/>
            <mass value="1.0" />
            <inertia ixx="100" ixy="0" ixz="0" iyy="100" iyz="0" izz="100" />
        </inertial>
        <visual>
            <origin xyz="0.0 0.13428331750888356 0.0" rpy="0 0 0"/>
            <geometry>
                <box size="0.6091581850811478 0.2685666350177671 0.6990115502782892" />
            </geometry>
            <material name="Green">
            <color rgba="0.164 0.776 0.478 1.0"/>
            </material>
        </visual>
        <collision>
            <origin xyz="0.0 0.13428331750888356 0.0" rpy="0 0 0"/>
            <geometry>
                <box size="0.6091581850811478 0.2685666350177671 0.6990115502782892" />
            </geometry>
        </collision>
    </link>
    <link name="Link9">
        <inertial>
            <origin xyz="0.3263628609597178 0.0 0.0" rpy="0 0 0"/>
            <mass value="1.0" />
            <inertia ixx="100" ixy="0" ixz="0" iyy="100" iyz="0" izz="100" />
        </inertial>
        <visual>
            <origin xyz="0.3263628609597178 0.0 0.0" rpy="0 0 0"/>
            <geometry>
                <box size="0.6527257219194356 0.3847987165516174 0.5588365642747419" />
            </geometry>
            <material name="Green">
            <color rgba="0.164 0.776 0.478 1.0"/>
            </material>
        </visual>
        <collision>
            <origin xyz="0.3263628609597178 0.0 0.0" rpy="0 0 0"/>
            <geometry>
                <box size="0.6527257219194356 0.3847987165516174 0.5588365642747419" />
            </geometry>
        </collision>
    </link>
    <link name="Link10">
        <inertial>
            <origin xyz="0.0 0.0 0.30328814200614407" rpy="0 0 0"/>
            <mass value="1.0" />
            <inertia ixx="100" ixy="0" ixz="0" iyy="100" iyz="0" izz="100" />
        </inertial>
        <visual>
            <origin xyz="0.0 0.0 0.30328814200614407" rpy="0 0 0"/>
            <geometry>
                <box size="0.532266400533705 0.6029296198736103 0.6065762840122881" />
            </geometry>
            <material name="Green">
            <color rgba="0.164 0.776 0.478 1.0"/>
            </material>
        </visual>
        <collision>
            <origin xyz="0.0 0.0 0.30328814200614407" rpy="0 0 0"/>
            <geometry>
                <box size="0.532266400533705 0.6029296198736103 0.6065762840122881" />
            </geometry>
        </collision>
    </link>
    <link name="Link11">
        <inertial>
            <origin xyz="0.18403984735605344 0.0 0.0" rpy="0 0 0"/>
            <mass value="1.0" />
            <inertia ixx="100" ixy="0" ixz="0" iyy="100" iyz="0" izz="100" />
        </inertial>
        <visual>
            <origin xyz="0.18403984735605344 0.0 0.0" rpy="0 0 0"/>
            <geometry>
                <box size="0.3680796947121069 0.25942182193394114 0.77908093017489" />
            </geometry>
            <material name="Blue">
            <color rgba="0.164 0.776 0.95 1.0"/>
            </material>
        </visual>
        <collision>
            <origin xyz="0.18403984735605344 0.0 0.0" rpy="0 0 0"/>
            <geometry>
                <box size="0.3680796947121069 0.25942182193394114 0.77908093017489" />
            </geometry>
        </collision>
    </link>
    <link name="Link12">
        <inertial>
            <origin xyz="0.0 -0.1133790611000142 0.0" rpy="0 0 0"/>
            <mass value="1.0" />
            <inertia ixx="100" ixy="0" ixz="0" iyy="100" iyz="0" izz="100" />
        </inertial>
        <visual>
            <origin xyz="0.0 -0.1133790611000142 0.0" rpy="0 0 0"/>
            <geometry>
                <box size="0.38067939315519744 0.2267581222000284 0.2802308990323772" />
            </geometry>
            <material name="Blue">
            <color rgba="0.164 0.776 0.95 1.0"/>
            </material>
        </visual>
        <collision>
            <origin xyz="0.0 -0.1133790611000142 0.0" rpy="0 0 0"/>
            <geometry>
                <box size="0.38067939315519744 0.2267581222000284 0.2802308990323772" />
            </geometry>
        </collision>
    </link>
    <link name="Link13">
        <inertial>
            <origin xyz="0.0 -0.1831345407519708 0.0" rpy="0 0 0"/>
            <mass value="1.0" />
            <inertia ixx="100" ixy="0" ixz="0" iyy="100" iyz="0" izz="100" />
        </inertial>
        <visual>
            <origin xyz="0.0 -0.1831345407519708 0.0" rpy="0 0 0"/>
            <geometry>
                <box size="0.8397396035435276 0.3662690815039416 0.7874385170836204" />
            </geometry>
            <material name="Green">
            <color rgba="0.164 0.776 0.478 1.0"/>
            </material>
        </visual>
        <collision>
            <origin xyz="0.0 -0.1831345407519708 0.0" rpy="0 0 0"/>
            <geometry>
                <box size="0.8397396035435276 0.3662690815039416 0.7874385170836204" />
            </geometry>
        </collision>
    </link>
    <link name="Link14">
        <inertial>
            <origin xyz="-0.22353366610772205 0.0 0.0" rpy="0 0 0"/>
            <mass value="1.0" />
            <inertia ixx="100" ixy="0" ixz="0" iyy="100" iyz="0" izz="100" />
        </inertial>
        <visual>
            <origin xyz="-0.22353366610772205 0.0 0.0" rpy="0 0 0"/>
            <geometry>
                <box size="0.4470673322154441 0.5497413019376467 0.2784863225983141" />
            </geometry>
            <material name="Blue">
            <color rgba="0.164 0.776 0.95 1.0"/>
            </material>
        </visual>
        <collision>
            <origin xyz="-0.22353366610772205 0.0 0.0" rpy="0 0 0"/>
            <geometry>
                <box size="0.4470673322154441 0.5497413019376467 0.2784863225983141" />
            </geometry>
        </collision>
    </link>
    <link name="Link15">
        <inertial>
            <origin xyz="0.0 -0.12627170062814239 0.0" rpy="0 0 0"/>
            <mass value="1.0" />
            <inertia ixx="100" ixy="0" ixz="0" iyy="100" iyz="0" izz="100" />
        </inertial>
        <visual>
            <origin xyz="0.0 -0.12627170062814239 0.0" rpy="0 0 0"/>
            <geometry>
                <box size="0.33507549632677747 0.25254340125628477 0.7444250948712121" />
            </geometry>
            <material name="Blue">
            <color rgba="0.164 0.776 0.95 1.0"/>
            </material>
        </visual>
        <collision>
            <origin xyz="0.0 -0.12627170062814239 0.0" rpy="0 0 0"/>
            <geometry>
                <box size="0.33507549632677747 0.25254340125628477 0.7444250948712121" />
            </geometry>
        </collision>
    </link>
    <link name="Link16">
        <inertial>
            <origin xyz="-0.2594505251933455 0.0 0.0" rpy="0 0 0"/>
            <mass value="1.0" />
            <inertia ixx="100" ixy="0" ixz="0" iyy="100" iyz="0" izz="100" />
        </inertial>
        <visual>
            <origin xyz="-0.2594505251933455 0.0 0.0" rpy="0 0 0"/>
            <geometry>
                <box size="0.518901050386691 0.7259055482103389 0.4759191360559103" />
            </geometry>
            <material name="Blue">
            <color rgba="0.164 0.776 0.95 1.0"/>
            </material>
        </visual>
        <collision>
            <origin xyz="-0.2594505251933455 0.0 0.0" rpy="0 0 0"/>
            <geometry>
                <box size="0.518901050386691 0.7259055482103389 0.4759191360559103" />
            </geometry>
        </collision>
    </link>
    <link name="Link17">
        <inertial>
            <origin xyz="-0.1394765917128493 0.0 0.0" rpy="0 0 0"/>
            <mass value="1.0" />
            <inertia ixx="100" ixy="0" ixz="0" iyy="100" iyz="0" izz="100" />
        </inertial>
        <visual>
            <origin xyz="-0.1394765917128493 0.0 0.0" rpy="0 0 0"/>
            <geometry>
                <box size="0.2789531834256986 0.6302854920797372 0.2155710551750848" />
            </geometry>
            <material name="Green">
            <color rgba="0.164 0.776 0.478 1.0"/>
            </material>
        </visual>
        <collision>
            <origin xyz="-0.1394765917128493 0.0 0.0" rpy="0 0 0"/>
            <geometry>
                <box size="0.2789531834256986 0.6302854920797372 0.2155710551750848" />
            </geometry>
        </collision>
    </link>
    <link name="Link18">
        <inertial>
            <origin xyz="0.0 0.0 -0.2796243564688454" rpy="0 0 0"/>
            <mass value="1.0" />
            <inertia ixx="100" ixy="0" ixz="0" iyy="100" iyz="0" izz="100" />
        </inertial>
        <visual>
            <origin xyz="0.0 0.0 -0.2796243564688454" rpy="0 0 0"/>
            <geometry>
                <box size="0.8702265089900802 0.8737019562371378 0.5592487129376909" />
            </geometry>
            <material name="Green">
            <color rgba="0.164 0.776 0.478 1.0"/>
            </material>
        </visual>
        <collision>
            <origin xyz="0.0 0.0 -0.2796243564688454" rpy="0 0 0"/>
            <geometry>
                <box size="0.8702265089900802 0.8737019562371378 0.5592487129376909" />
            </geometry>
        </collision>
    </link>
    <joint name="Link0_Link1" type="revolute">
       <parent link="Link0"/>
       <child  link="Link1"/>
       <origin rpy="0 0 0" xyz="0.4194883330994753 0.0 2.292481967982776" />
     <axis xyz="1 0 0"/>
       <limit effort="0.0" lower="-3.14159" upper="3.14159" velocity="0.0"/>
    </joint>
    <joint name="Link0_Link2" type="revolute">
       <parent link="Link0"/>
       <child  link="Link2"/>
       <origin rpy="0 0 0" xyz="0.0 0.2269817773168025 2.292481967982776" />
     <axis xyz="0 1 0"/>
       <limit effort="0.0" lower="-3.14159" upper="3.14159" velocity="0.0"/>
    </joint>
    <joint name="Link1_Link3" type="revolute">
       <parent link="Link1"/>
       <child  link="Link3"/>
       <origin rpy="0 0 0" xyz="0.5466070143580388 0.0 0.0" />
     <axis xyz="1 0 0"/>
       <limit effort="0.0" lower="-3.14159" upper="3.14159" velocity="0.0"/>
    </joint>
    <joint name="Link2_Link4" type="revolute">
       <parent link="Link2"/>
       <child  link="Link4"/>
       <origin rpy="0 0 0" xyz="-0.4967864512689961 0.3329734312469218 0.0" />
     <axis xyz="1 0 0"/>
       <limit effort="0.0" lower="-3.14159" upper="3.14159" velocity="0.0"/>
    </joint>
    <joint name="Link0_Link5" type="revolute">
       <parent link="Link0"/>
       <child  link="Link5"/>
       <origin rpy="0 0 0" xyz="0.0 0.0 2.0" />
     <axis xyz="1 0 0"/>
       <limit effort="0.0" lower="-3.14159" upper="3.14159" velocity="0.0"/>
    </joint>
    <joint name="Link4_Link6" type="revolute">
       <parent link="Link4"/>
       <child  link="Link6"/>
       <origin rpy="0 0 0" xyz="-0.48988876966203454 0.0 -0.28005250253323366" />
     <axis xyz="0 1 0"/>
       <limit effort="0.0" lower="-3.14159" upper="3.14159" velocity="0.0"/>
    </joint>
    <joint name="Link5_Link7" type="revolute">
       <parent link="Link5"/>
       <child  link="Link7"/>
       <origin rpy="0 0 0" xyz="0.0 -0.13912306636619692 -0.3871397556762428" />
     <axis xyz="1 0 0"/>
       <limit effort="0.0" lower="-3.14159" upper="3.14159" velocity="0.0"/>
    </joint>
    <joint name="Link3_Link8" type="revolute">
       <parent link="Link3"/>
       <child  link="Link8"/>
       <origin rpy="0 0 0" xyz="0.36802994126815036 0.4684585783517753 0.0" />
     <axis xyz="0 1 0"/>
       <limit effort="0.0" lower="-3.14159" upper="3.14159" velocity="0.0"/>
    </joint>
    <joint name="Link3_Link9" type="revolute">
       <parent link="Link3"/>
       <child  link="Link9"/>
       <origin rpy="0 0 0" xyz="0.7360598825363008 0.0 0.0" />
     <axis xyz="1 0 0"/>
       <limit effort="0.0" lower="-3.14159" upper="3.14159" velocity="0.0"/>
    </joint>
    <joint name="Link3_Link10" type="fixed">
       <parent link="Link3"/>
       <child  link="Link10"/>
       <origin rpy="0 0 0" xyz="0.36802994126815036 0.0 0.2138378712929181" />
     <axis xyz="0 1 0"/>
       <limit effort="0.0" lower="-3.14159" upper="3.14159" velocity="0.0"/>
    </joint>
    <joint name="Link9_Link11" type="revolute">
       <parent link="Link9"/>
       <child  link="Link11"/>
       <origin rpy="0 0 0" xyz="0.6527257219194356 0.0 0.0" />
     <axis xyz="0 1 0"/>
       <limit effort="0.0" lower="-3.14159" upper="3.14159" velocity="0.0"/>
    </joint>
    <joint name="Link4_Link12" type="revolute">
       <parent link="Link4"/>
       <child  link="Link12"/>
       <origin rpy="0 0 0" xyz="-0.48988876966203454 -0.3834893078210604 0.0" />
     <axis xyz="0 1 0"/>
       <limit effort="0.0" lower="-3.14159" upper="3.14159" velocity="0.0"/>
    </joint>
    <joint name="Link0_Link13" type="revolute">
       <parent link="Link0"/>
       <child  link="Link13"/>
       <origin rpy="0 0 0" xyz="0.0 -0.2269817773168025 2.292481967982776" />
     <axis xyz="0 1 0"/>
       <limit effort="0.0" lower="-3.14159" upper="3.14159" velocity="0.0"/>
    </joint>
    <joint name="Link4_Link14" type="revolute">
       <parent link="Link4"/>
       <child  link="Link14"/>
       <origin rpy="0 0 0" xyz="-0.9797775393240691 0.0 0.0" />
     <axis xyz="1 0 0"/>
       <limit effort="0.0" lower="-3.14159" upper="3.14159" velocity="0.0"/>
    </joint>
    <joint name="Link13_Link15" type="fixed">
       <parent link="Link13"/>
       <child  link="Link15"/>
       <origin rpy="0 0 0" xyz="0.0 -0.36626908150394166 0.0" />
     <axis xyz="0 1 0"/>
       <limit effort="0.0" lower="-3.14159" upper="3.14159" velocity="0.0"/>
    </joint>
    <joint name="Link14_Link16" type="fixed">
       <parent link="Link14"/>
       <child  link="Link16"/>
       <origin rpy="0 0 0" xyz="-0.44706733221544415 0.0 0.0" />
     <axis xyz="0 1 0"/>
       <limit effort="0.0" lower="-3.14159" upper="3.14159" velocity="0.0"/>
    </joint>
    <joint name="Link7_Link17" type="revolute">
       <parent link="Link7"/>
       <child  link="Link17"/>
       <origin rpy="0 0 0" xyz="-0.3201630488609736 -0.4276269787566777 0.0" />
     <axis xyz="0 1 0"/>
       <limit effort="0.0" lower="-3.14159" upper="3.14159" velocity="0.0"/>
    </joint>
    <joint name="Link6_Link18" type="fixed">
       <parent link="Link6"/>
       <child  link="Link18"/>
       <origin rpy="0 0 0" xyz="0.0 0.0 -0.6646461504802514" />
     <axis xyz="0 1 0"/>
       <limit effort="0.0" lower="-3.14159" upper="3.14159" velocity="0.0"/>
    </joint>
</robot>