<robot name = "robot">
    <link name="Link0">
        <inertial>
            <origin xyz="0 0 3" rpy="0 0 0"/>
            <mass value="1.0" />
            <inertia ixx="100" ixy="0" ixz="0" iyy="100" iyz="0" izz="100" />
        </inertial>
        <visual>
            <origin xyz="0 0 3" rpy="0 0 0"/>
            <geometry>
                <box size="1 1 1" />
            </geometry>
            <material name="Blue">
            <color rgba="0.164 0.776 0.95 1.0"/>
            </material>
        </visual>
        <collision>
            <origin xyz="0 0 3" rpy="0 0 0"/>
            <geometry>
                <box size="1 1 1" />
            </geometry>
        </collision>
    </link>
    <link name="Link1">
        <inertial>
            <origin xyz="0.0 0.0 -0.21706067140501467" rpy="0 0 0"/>
            <mass value="1.0" />
            <inertia ixx="100" ixy="0" ixz="0" iyy="100" iyz="0" izz="100" />
        </inertial>
        <visual>
            <origin xyz="0.0 0.0 -0.21706067140501467" rpy="0 0 0"/>
            <geometry>
                <box size="0.5262809345565843 0.6233285842077725 0.43412134281002934" />
            </geometry>
            <material name="Green">
            <color rgba="0.164 0.776 0.478 1.0"/>
            </material>
        </visual>
        <collision>
            <origin xyz="0.0 0.0 -0.21706067140501467" rpy="0 0 0"/>
            <geometry>
                <box size="0.5262809345565843 0.6233285842077725 0.43412134281002934" />
            </geometry>
        </collision>
    </link>
    <link name="Link2">
        <inertial>
            <origin xyz="0.0 0.2904727677726907 0.0" rpy="0 0 0"/>
            <mass value="1.0" />
            <inertia ixx="100" ixy="0" ixz="0" iyy="100" iyz="0" izz="100" />
        </inertial>
        <visual>
            <origin xyz="0.0 0.2904727677726907 0.0" rpy="0 0 0"/>
            <geometry>
                <box size="0.4966533370659835 0.5809455355453814 0.36299143987659693" />
            </geometry>
            <material name="Green">
            <color rgba="0.164 0.776 0.478 1.0"/>
            </material>
        </visual>
        <collision>
            <origin xyz="0.0 0.2904727677726907 0.0" rpy="0 0 0"/>
            <geometry>
                <box size="0.4966533370659835 0.5809455355453814 0.36299143987659693" />
            </geometry>
        </collision>
    </link>
    <link name="Link3">
        <inertial>
            <origin xyz="0.41262875609448946 0.0 0.0" rpy="0 0 0"/>
            <mass value="1.0" />
            <inertia ixx="100" ixy="0" ixz="0" iyy="100" iyz="0" izz="100" />
        </inertial>
        <visual>
            <origin xyz="0.41262875609448946 0.0 0.0" rpy="0 0 0"/>
            <geometry>
                <box size="0.8252575121889789 0.7703902107821214 0.3232071424828853" />
            </geometry>
            <material name="Blue">
            <color rgba="0.164 0.776 0.95 1.0"/>
            </material>
        </visual>
        <collision>
            <origin xyz="0.41262875609448946 0.0 0.0" rpy="0 0 0"/>
            <geometry>
                <box size="0.8252575121889789 0.7703902107821214 0.3232071424828853" />
            </geometry>
        </collision>
    </link>
    <link name="Link4">
        <inertial>
            <origin xyz="0.0 0.37976423708626 0.0" rpy="0 0 0"/>
            <mass value="1.0" />
            <inertia ixx="100" ixy="0" ixz="0" iyy="100" iyz="0" izz="100" />
        </inertial>
        <visual>
            <origin xyz="0.0 0.37976423708626 0.0" rpy="0 0 0"/>
            <geometry>
                <box size="0.7023040552536451 0.75952847417252 0.7323070479985292" />
            </geometry>
            <material name="Blue">
            <color rgba="0.164 0.776 0.95 1.0"/>
            </material>
        </visual>
        <collision>
            <origin xyz="0.0 0.37976423708626 0.0" rpy="0 0 0"/>
            <geometry>
                <box size="0.7023040552536451 0.75952847417252 0.7323070479985292" />
            </geometry>
        </collision>
    </link>
    <link name="Link5">
        <inertial>
            <origin xyz="0.0 -0.1657295351263626 0.0" rpy="0 0 0"/>
            <mass value="1.0" />
            <inertia ixx="100" ixy="0" ixz="0" iyy="100" iyz="0" izz="100" />
        </inertial>
        <visual>
            <origin xyz="0.0 -0.1657295351263626 0.0" rpy="0 0 0"/>
            <geometry>
                <box size="0.489859601176537 0.3314590702527252 0.3230590819206055" />
            </geometry>
            <material name="Green">
            <color rgba="0.164 0.776 0.478 1.0"/>
            </material>
        </visual>
        <collision>
            <origin xyz="0.0 -0.1657295351263626 0.0" rpy="0 0 0"/>
            <geometry>
                <box size="0.489859601176537 0.3314590702527252 0.3230590819206055" />
            </geometry>
        </collision>
    </link>
    <link name="Link6">
        <inertial>
            <origin xyz="0.0 0.0 0.16355040706910498" rpy="0 0 0"/>
            <mass value="1.0" />
            <inertia ixx="100" ixy="0" ixz="0" iyy="100" iyz="0" izz="100" />
        </inertial>
        <visual>
            <origin xyz="0.0 0.0 0.16355040706910498" rpy="0 0 0"/>
            <geometry>
                <box size="0.6083611446364667 0.40323248989241717 0.32710081413820996" />
            </geometry>
            <material name="Blue">
            <color rgba="0.164 0.776 0.95 1.0"/>
            </material>
        </visual>
        <collision>
            <origin xyz="0.0 0.0 0.16355040706910498" rpy="0 0 0"/>
            <geometry>
                <box size="0.6083611446364667 0.40323248989241717 0.32710081413820996" />
            </geometry>
        </collision>
    </link>
    <link name="Link7">
        <inertial>
            <origin xyz="0.17484516576172002 0.0 0.0" rpy="0 0 0"/>
            <mass value="1.0" />
            <inertia ixx="100" ixy="0" ixz="0" iyy="100" iyz="0" izz="100" />
        </inertial>
        <visual>
            <origin xyz="0.17484516576172002 0.0 0.0" rpy="0 0 0"/>
            <geometry>
                <box size="0.34969033152344003 0.30439741796450637 0.31175367264705073" />
            </geometry>
            <material name="Blue">
            <color rgba="0.164 0.776 0.95 1.0"/>
            </material>
        </visual>
        <collision>
            <origin xyz="0.17484516576172002 0.0 0.0" rpy="0 0 0"/>
            <geometry>
                <box size="0.34969033152344003 0.30439741796450637 0.31175367264705073" />
            </geometry>
        </collision>
    </link>
    <joint name="Link0_Link1" type="revolute">
       <parent link="Link0"/>
       <child  link="Link1"/>
       <origin rpy="0 0 0" xyz="0.0 0.0 2.5" />
     <axis xyz="0 0 1"/>
       <limit effort="0.0" lower="-3.14159" upper="3.14159" velocity="0.0"/>
    </joint>
    <joint name="Link1_Link2" type="revolute">
       <parent link="Link1"/>
       <child  link="Link2"/>
       <origin rpy="0 0 0" xyz="0.0 0.31166429210388624 -0.21706067140501473" />
     <axis xyz="0 1 0"/>
       <limit effort="0.0" lower="-3.14159" upper="3.14159" velocity="0.0"/>
    </joint>
    <joint name="Link0_Link3" type="revolute">
       <parent link="Link0"/>
       <child  link="Link3"/>
       <origin rpy="0 0 0" xyz="0.5 0.0 3.0" />
     <axis xyz="1 0 0"/>
       <limit effort="0.0" lower="-3.14159" upper="3.14159" velocity="0.0"/>
    </joint>
    <joint name="Link0_Link4" type="revolute">
       <parent link="Link0"/>
       <child  link="Link4"/>
       <origin rpy="0 0 0" xyz="0.0 0.5 3.0" />
     <axis xyz="0 0 1"/>
       <limit effort="0.0" lower="-3.14159" upper="3.14159" velocity="0.0"/>
    </joint>
    <joint name="Link3_Link5" type="revolute">
       <parent link="Link3"/>
       <child  link="Link5"/>
       <origin rpy="0 0 0" xyz="0.41262875609448946 -0.3851951053910607 0.0" />
     <axis xyz="0 1 0"/>
       <limit effort="0.0" lower="-3.14159" upper="3.14159" velocity="0.0"/>
    </joint>
    <joint name="Link4_Link6" type="revolute">
       <parent link="Link4"/>
       <child  link="Link6"/>
       <origin rpy="0 0 0" xyz="0.0 0.37976423708625995 0.3661535239992646" />
     <axis xyz="0 1 0"/>
       <limit effort="0.0" lower="-3.14159" upper="3.14159" velocity="0.0"/>
    </joint>
    <joint name="Link6_Link7" type="revolute">
       <parent link="Link6"/>
       <child  link="Link7"/>
       <origin rpy="0 0 0" xyz="0.30418057231823337 0.0 0.16355040706910495" />
     <axis xyz="1 0 0"/>
       <limit effort="0.0" lower="-3.14159" upper="3.14159" velocity="0.0"/>
    </joint>
</robot>