<robot name = "robot">
    <link name="Link0">
        <inertial>
            <origin xyz="0 0 3" rpy="0 0 0"/>
            <mass value="1.0" />
            <inertia ixx="100" ixy="0" ixz="0" iyy="100" iyz="0" izz="100" />
        </inertial>
        <visual>
            <origin xyz="0 0 3" rpy="0 0 0"/>
            <geometry>
                <box size="1 1 1" />
            </geometry>
            <material name="Blue">
            <color rgba="0.164 0.776 0.95 1.0"/>
            </material>
        </visual>
        <collision>
            <origin xyz="0 0 3" rpy="0 0 0"/>
            <geometry>
                <box size="1 1 1" />
            </geometry>
        </collision>
    </link>
    <link name="Link1">
        <inertial>
            <origin xyz="0.0 0.0 0.31893165348228836" rpy="0 0 0"/>
            <mass value="1.0" />
            <inertia ixx="100" ixy="0" ixz="0" iyy="100" iyz="0" izz="100" />
        </inertial>
        <visual>
            <origin xyz="0.0 0.0 0.31893165348228836" rpy="0 0 0"/>
            <geometry>
                <box size="0.377580183909428 0.9775863589874136 0.6378633069645767" />
            </geometry>
            <material name="Green">
            <color rgba="0.164 0.776 0.478 1.0"/>
            </material>
        </visual>
        <collision>
            <origin xyz="0.0 0.0 0.31893165348228836" rpy="0 0 0"/>
            <geometry>
                <box size="0.377580183909428 0.9775863589874136 0.6378633069645767" />
            </geometry>
        </collision>
    </link>
    <link name="Link2">
        <inertial>
            <origin xyz="0.0 -0.3078001965705137 0.0" rpy="0 0 0"/>
            <mass value="1.0" />
            <inertia ixx="100" ixy="0" ixz="0" iyy="100" iyz="0" izz="100" />
        </inertial>
        <visual>
            <origin xyz="0.0 -0.3078001965705137 0.0" rpy="0 0 0"/>
            <geometry>
                <box size="0.31783029748980257 0.6156003931410274 0.5597216419292415" />
            </geometry>
            <material name="Blue">
            <color rgba="0.164 0.776 0.95 1.0"/>
            </material>
        </visual>
        <collision>
            <origin xyz="0.0 -0.3078001965705137 0.0" rpy="0 0 0"/>
            <geometry>
                <box size="0.31783029748980257 0.6156003931410274 0.5597216419292415" />
            </geometry>
        </collision>
    </link>
    <link name="Link3">
        <inertial>
            <origin xyz="-0.21456184814315585 0.0 0.0" rpy="0 0 0"/>
            <mass value="1.0" />
            <inertia ixx="100" ixy="0" ixz="0" iyy="100" iyz="0" izz="100" />
        </inertial>
        <visual>
            <origin xyz="-0.21456184814315585 0.0 0.0" rpy="0 0 0"/>
            <geometry>
                <box size="0.4291236962863117 0.8161941879835226 0.7710646603181537" />
            </geometry>
            <material name="Blue">
            <color rgba="0.164 0.776 0.95 1.0"/>
            </material>
        </visual>
        <collision>
            <origin xyz="-0.21456184814315585 0.0 0.0" rpy="0 0 0"/>
            <geometry>
                <box size="0.4291236962863117 0.8161941879835226 0.7710646603181537" />
            </geometry>
        </collision>
    </link>
    <link name="Link4">
        <inertial>
            <origin xyz="0.0 0.2573050179297238 0.0" rpy="0 0 0"/>
            <mass value="1.0" />
            <inertia ixx="100" ixy="0" ixz="0" iyy="100" iyz="0" izz="100" />
        </inertial>
        <visual>
            <origin xyz="0.0 0.2573050179297238 0.0" rpy="0 0 0"/>
            <geometry>
                <box size="0.36693064565178724 0.5146100358594476 0.4524504254168353" />
            </geometry>
            <material name="Blue">
            <color rgba="0.164 0.776 0.95 1.0"/>
            </material>
        </visual>
        <collision>
            <origin xyz="0.0 0.2573050179297238 0.0" rpy="0 0 0"/>
            <geometry>
                <box size="0.36693064565178724 0.5146100358594476 0.4524504254168353" />
            </geometry>
        </collision>
    </link>
    <joint name="Link0_Link1" type="revolute">
       <parent link="Link0"/>
       <child  link="Link1"/>
       <origin rpy="0 0 0" xyz="0.0 0.0 3.5" />
     <axis xyz="0 1 0"/>
       <limit effort="0.0" lower="-3.14159" upper="3.14159" velocity="0.0"/>
    </joint>
    <joint name="Link1_Link2" type="revolute">
       <parent link="Link1"/>
       <child  link="Link2"/>
       <origin rpy="0 0 0" xyz="0.0 -0.4887931794937068 0.31893165348228836" />
     <axis xyz="0 1 0"/>
       <limit effort="0.0" lower="-3.14159" upper="3.14159" velocity="0.0"/>
    </joint>
    <joint name="Link0_Link3" type="revolute">
       <parent link="Link0"/>
       <child  link="Link3"/>
       <origin rpy="0 0 0" xyz="-0.5 0.0 3.0" />
     <axis xyz="0 1 0"/>
       <limit effort="0.0" lower="-3.14159" upper="3.14159" velocity="0.0"/>
    </joint>
    <joint name="Link3_Link4" type="revolute">
       <parent link="Link3"/>
       <child  link="Link4"/>
       <origin rpy="0 0 0" xyz="-0.21456184814315582 0.4080970939917613 0.0" />
     <axis xyz="1 0 0"/>
       <limit effort="0.0" lower="-3.14159" upper="3.14159" velocity="0.0"/>
    </joint>
</robot>