<robot name = "robot">
    <link name="Link0">
        <inertial>
            <origin xyz="0 0 3" rpy="0 0 0"/>
            <mass value="1.0" />
            <inertia ixx="100" ixy="0" ixz="0" iyy="100" iyz="0" izz="100" />
        </inertial>
        <visual>
            <origin xyz="0 0 3" rpy="0 0 0"/>
            <geometry>
                <box size="1 1 1" />
            </geometry>
            <material name="Blue">
            <color rgba="0.164 0.776 0.95 1.0"/>
            </material>
        </visual>
        <collision>
            <origin xyz="0 0 3" rpy="0 0 0"/>
            <geometry>
                <box size="1 1 1" />
            </geometry>
        </collision>
    </link>
    <link name="Link1">
        <inertial>
            <origin xyz="0.16275011972332484 0.0 0.0" rpy="0 0 0"/>
            <mass value="1.0" />
            <inertia ixx="100" ixy="0" ixz="0" iyy="100" iyz="0" izz="100" />
        </inertial>
        <visual>
            <origin xyz="0.16275011972332484 0.0 0.0" rpy="0 0 0"/>
            <geometry>
                <box size="0.3255002394466497 0.47669606348320653 0.618929605782129" />
            </geometry>
            <material name="Green">
            <color rgba="0.164 0.776 0.478 1.0"/>
            </material>
        </visual>
        <collision>
            <origin xyz="0.16275011972332484 0.0 0.0" rpy="0 0 0"/>
            <geometry>
                <box size="0.3255002394466497 0.47669606348320653 0.618929605782129" />
            </geometry>
        </collision>
    </link>
    <link name="Link2">
        <inertial>
            <origin xyz="0.0 0.0 -0.22586055186673484" rpy="0 0 0"/>
            <mass value="1.0" />
            <inertia ixx="100" ixy="0" ixz="0" iyy="100" iyz="0" izz="100" />
        </inertial>
        <visual>
            <origin xyz="0.0 0.0 -0.22586055186673484" rpy="0 0 0"/>
            <geometry>
                <box size="0.3218968741477133 0.4486367991551453 0.4517211037334697" />
            </geometry>
            <material name="Green">
            <color rgba="0.164 0.776 0.478 1.0"/>
            </material>
        </visual>
        <collision>
            <origin xyz="0.0 0.0 -0.22586055186673484" rpy="0 0 0"/>
            <geometry>
                <box size="0.3218968741477133 0.4486367991551453 0.4517211037334697" />
            </geometry>
        </collision>
    </link>
    <link name="Link3">
        <inertial>
            <origin xyz="0.0 -0.15583576557172085 0.0" rpy="0 0 0"/>
            <mass value="1.0" />
            <inertia ixx="100" ixy="0" ixz="0" iyy="100" iyz="0" izz="100" />
        </inertial>
        <visual>
            <origin xyz="0.0 -0.15583576557172085 0.0" rpy="0 0 0"/>
            <geometry>
                <box size="0.32116579902260267 0.3116715311434417 0.5667140145257691" />
            </geometry>
            <material name="Blue">
            <color rgba="0.164 0.776 0.95 1.0"/>
            </material>
        </visual>
        <collision>
            <origin xyz="0.0 -0.15583576557172085 0.0" rpy="0 0 0"/>
            <geometry>
                <box size="0.32116579902260267 0.3116715311434417 0.5667140145257691" />
            </geometry>
        </collision>
    </link>
    <link name="Link4">
        <inertial>
            <origin xyz="0.0 0.0 0.2137996740400458" rpy="0 0 0"/>
            <mass value="1.0" />
            <inertia ixx="100" ixy="0" ixz="0" iyy="100" iyz="0" izz="100" />
        </inertial>
        <visual>
            <origin xyz="0.0 0.0 0.2137996740400458" rpy="0 0 0"/>
            <geometry>
                <box size="0.31927517709244047 0.301665342824833 0.4275993480800916" />
            </geometry>
            <material name="Blue">
            <color rgba="0.164 0.776 0.95 1.0"/>
            </material>
        </visual>
        <collision>
            <origin xyz="0.0 0.0 0.2137996740400458" rpy="0 0 0"/>
            <geometry>
                <box size="0.31927517709244047 0.301665342824833 0.4275993480800916" />
            </geometry>
        </collision>
    </link>
    <link name="Link5">
        <inertial>
            <origin xyz="0.15340689363265295 0.0 0.0" rpy="0 0 0"/>
            <mass value="1.0" />
            <inertia ixx="100" ixy="0" ixz="0" iyy="100" iyz="0" izz="100" />
        </inertial>
        <visual>
            <origin xyz="0.15340689363265295 0.0 0.0" rpy="0 0 0"/>
            <geometry>
                <box size="0.3068137872653059 0.3150538323653001 0.3200662814211712" />
            </geometry>
            <material name="Blue">
            <color rgba="0.164 0.776 0.95 1.0"/>
            </material>
        </visual>
        <collision>
            <origin xyz="0.15340689363265295 0.0 0.0" rpy="0 0 0"/>
            <geometry>
                <box size="0.3068137872653059 0.3150538323653001 0.3200662814211712" />
            </geometry>
        </collision>
    </link>
    <link name="Link6">
        <inertial>
            <origin xyz="0.160357335490451 0.0 0.0" rpy="0 0 0"/>
            <mass value="1.0" />
            <inertia ixx="100" ixy="0" ixz="0" iyy="100" iyz="0" izz="100" />
        </inertial>
        <visual>
            <origin xyz="0.160357335490451 0.0 0.0" rpy="0 0 0"/>
            <geometry>
                <box size="0.320714670980902 0.3116520919501601 0.48703270932386633" />
            </geometry>
            <material name="Green">
            <color rgba="0.164 0.776 0.478 1.0"/>
            </material>
        </visual>
        <collision>
            <origin xyz="0.160357335490451 0.0 0.0" rpy="0 0 0"/>
            <geometry>
                <box size="0.320714670980902 0.3116520919501601 0.48703270932386633" />
            </geometry>
        </collision>
    </link>
    <link name="Link7">
        <inertial>
            <origin xyz="0.15173284550727223 0.0 0.0" rpy="0 0 0"/>
            <mass value="1.0" />
            <inertia ixx="100" ixy="0" ixz="0" iyy="100" iyz="0" izz="100" />
        </inertial>
        <visual>
            <origin xyz="0.15173284550727223 0.0 0.0" rpy="0 0 0"/>
            <geometry>
                <box size="0.30346569101454446 0.30605702265811324 0.3106613976181349" />
            </geometry>
            <material name="Blue">
            <color rgba="0.164 0.776 0.95 1.0"/>
            </material>
        </visual>
        <collision>
            <origin xyz="0.15173284550727223 0.0 0.0" rpy="0 0 0"/>
            <geometry>
                <box size="0.30346569101454446 0.30605702265811324 0.3106613976181349" />
            </geometry>
        </collision>
    </link>
    <link name="Link8">
        <inertial>
            <origin xyz="-0.3663539705651386 0.0 0.0" rpy="0 0 0"/>
            <mass value="1.0" />
            <inertia ixx="100" ixy="0" ixz="0" iyy="100" iyz="0" izz="100" />
        </inertial>
        <visual>
            <origin xyz="-0.3663539705651386 0.0 0.0" rpy="0 0 0"/>
            <geometry>
                <box size="0.7327079411302772 0.5806001636715341 0.40013790577633906" />
            </geometry>
            <material name="Blue">
            <color rgba="0.164 0.776 0.95 1.0"/>
            </material>
        </visual>
        <collision>
            <origin xyz="-0.3663539705651386 0.0 0.0" rpy="0 0 0"/>
            <geometry>
                <box size="0.7327079411302772 0.5806001636715341 0.40013790577633906" />
            </geometry>
        </collision>
    </link>
    <link name="Link9">
        <inertial>
            <origin xyz="0.0 0.0 -0.15385402563697384" rpy="0 0 0"/>
            <mass value="1.0" />
            <inertia ixx="100" ixy="0" ixz="0" iyy="100" iyz="0" izz="100" />
        </inertial>
        <visual>
            <origin xyz="0.0 0.0 -0.15385402563697384" rpy="0 0 0"/>
            <geometry>
                <box size="0.3012902669237104 0.30704501924404765 0.3077080512739477" />
            </geometry>
            <material name="Blue">
            <color rgba="0.164 0.776 0.95 1.0"/>
            </material>
        </visual>
        <collision>
            <origin xyz="0.0 0.0 -0.15385402563697384" rpy="0 0 0"/>
            <geometry>
                <box size="0.3012902669237104 0.30704501924404765 0.3077080512739477" />
            </geometry>
        </collision>
    </link>
    <joint name="Link0_Link1" type="revolute">
       <parent link="Link0"/>
       <child  link="Link1"/>
       <origin rpy="0 0 0" xyz="0.5 0.0 3.0" />
     <axis xyz="0 0 1"/>
       <limit effort="0.0" lower="-3.14159" upper="3.14159" velocity="0.0"/>
    </joint>
    <joint name="Link1_Link2" type="revolute">
       <parent link="Link1"/>
       <child  link="Link2"/>
       <origin rpy="0 0 0" xyz="0.16275011972332487 0.0 -0.3094648028910645" />
     <axis xyz="0 1 0"/>
       <limit effort="0.0" lower="-3.14159" upper="3.14159" velocity="0.0"/>
    </joint>
    <joint name="Link1_Link3" type="revolute">
       <parent link="Link1"/>
       <child  link="Link3"/>
       <origin rpy="0 0 0" xyz="0.16275011972332487 -0.23834803174160327 0.0" />
     <axis xyz="1 0 0"/>
       <limit effort="0.0" lower="-3.14159" upper="3.14159" velocity="0.0"/>
    </joint>
    <joint name="Link3_Link4" type="revolute">
       <parent link="Link3"/>
       <child  link="Link4"/>
       <origin rpy="0 0 0" xyz="0.0 -0.15583576557172082 0.2833570072628846" />
     <axis xyz="0 0 1"/>
       <limit effort="0.0" lower="-3.14159" upper="3.14159" velocity="0.0"/>
    </joint>
    <joint name="Link1_Link5" type="revolute">
       <parent link="Link1"/>
       <child  link="Link5"/>
       <origin rpy="0 0 0" xyz="0.32550023944664974 0.0 0.0" />
     <axis xyz="1 0 0"/>
       <limit effort="0.0" lower="-3.14159" upper="3.14159" velocity="0.0"/>
    </joint>
    <joint name="Link3_Link6" type="revolute">
       <parent link="Link3"/>
       <child  link="Link6"/>
       <origin rpy="0 0 0" xyz="0.16058289951130134 -0.15583576557172082 0.0" />
     <axis xyz="0 0 1"/>
       <limit effort="0.0" lower="-3.14159" upper="3.14159" velocity="0.0"/>
    </joint>
    <joint name="Link5_Link7" type="revolute">
       <parent link="Link5"/>
       <child  link="Link7"/>
       <origin rpy="0 0 0" xyz="0.30681378726530584 0.0 0.0" />
     <axis xyz="0 1 0"/>
       <limit effort="0.0" lower="-3.14159" upper="3.14159" velocity="0.0"/>
    </joint>
    <joint name="Link0_Link8" type="revolute">
       <parent link="Link0"/>
       <child  link="Link8"/>
       <origin rpy="0 0 0" xyz="-0.5 0.0 3.0" />
     <axis xyz="0 1 0"/>
       <limit effort="0.0" lower="-3.14159" upper="3.14159" velocity="0.0"/>
    </joint>
    <joint name="Link5_Link9" type="revolute">
       <parent link="Link5"/>
       <child  link="Link9"/>
       <origin rpy="0 0 0" xyz="0.15340689363265292 0.0 -0.16003314071058572" />
     <axis xyz="1 0 0"/>
       <limit effort="0.0" lower="-3.14159" upper="3.14159" velocity="0.0"/>
    </joint>
</robot>