<robot name = "robot">
    <link name="Link0">
        <inertial>
            <origin xyz="0 0 3" rpy="0 0 0"/>
            <mass value="1.0" />
            <inertia ixx="100" ixy="0" ixz="0" iyy="100" iyz="0" izz="100" />
        </inertial>
        <visual>
            <origin xyz="0 0 3" rpy="0 0 0"/>
            <geometry>
                <box size="1 1 1" />
            </geometry>
            <material name="Blue">
            <color rgba="0.164 0.776 0.95 1.0"/>
            </material>
        </visual>
        <collision>
            <origin xyz="0 0 3" rpy="0 0 0"/>
            <geometry>
                <box size="1 1 1" />
            </geometry>
        </collision>
    </link>
    <link name="Link1">
        <inertial>
            <origin xyz="0.0 0.0 0.40896450115897576" rpy="0 0 0"/>
            <mass value="1.0" />
            <inertia ixx="100" ixy="0" ixz="0" iyy="100" iyz="0" izz="100" />
        </inertial>
        <visual>
            <origin xyz="0.0 0.0 0.40896450115897576" rpy="0 0 0"/>
            <geometry>
                <box size="0.8566354958959876 0.9597151986439352 0.8179290023179515" />
            </geometry>
            <material name="Green">
            <color rgba="0.164 0.776 0.478 1.0"/>
            </material>
        </visual>
        <collision>
            <origin xyz="0.0 0.0 0.40896450115897576" rpy="0 0 0"/>
            <geometry>
                <box size="0.8566354958959876 0.9597151986439352 0.8179290023179515" />
            </geometry>
        </collision>
    </link>
    <link name="Link2">
        <inertial>
            <origin xyz="0.0 -0.4653151721127179 0.0" rpy="0 0 0"/>
            <mass value="1.0" />
            <inertia ixx="100" ixy="0" ixz="0" iyy="100" iyz="0" izz="100" />
        </inertial>
        <visual>
            <origin xyz="0.0 -0.4653151721127179 0.0" rpy="0 0 0"/>
            <geometry>
                <box size="0.7542821871958469 0.9306303442254358 0.37924417525720105" />
            </geometry>
            <material name="Green">
            <color rgba="0.164 0.776 0.478 1.0"/>
            </material>
        </visual>
        <collision>
            <origin xyz="0.0 -0.4653151721127179 0.0" rpy="0 0 0"/>
            <geometry>
                <box size="0.7542821871958469 0.9306303442254358 0.37924417525720105" />
            </geometry>
        </collision>
    </link>
    <link name="Link3">
        <inertial>
            <origin xyz="0.20067488869876748 0.0 0.0" rpy="0 0 0"/>
            <mass value="1.0" />
            <inertia ixx="100" ixy="0" ixz="0" iyy="100" iyz="0" izz="100" />
        </inertial>
        <visual>
            <origin xyz="0.20067488869876748 0.0 0.0" rpy="0 0 0"/>
            <geometry>
                <box size="0.40134977739753497 0.8722759486911733 0.5017008782555205" />
            </geometry>
            <material name="Green">
            <color rgba="0.164 0.776 0.478 1.0"/>
            </material>
        </visual>
        <collision>
            <origin xyz="0.20067488869876748 0.0 0.0" rpy="0 0 0"/>
            <geometry>
                <box size="0.40134977739753497 0.8722759486911733 0.5017008782555205" />
            </geometry>
        </collision>
    </link>
    <link name="Link4">
        <inertial>
            <origin xyz="0.0 0.1505078554753758 0.0" rpy="0 0 0"/>
            <mass value="1.0" />
            <inertia ixx="100" ixy="0" ixz="0" iyy="100" iyz="0" izz="100" />
        </inertial>
        <visual>
            <origin xyz="0.0 0.1505078554753758 0.0" rpy="0 0 0"/>
            <geometry>
                <box size="0.3128409390154083 0.3010157109507516 0.4757631023269153" />
            </geometry>
            <material name="Blue">
            <color rgba="0.164 0.776 0.95 1.0"/>
            </material>
        </visual>
        <collision>
            <origin xyz="0.0 0.1505078554753758 0.0" rpy="0 0 0"/>
            <geometry>
                <box size="0.3128409390154083 0.3010157109507516 0.4757631023269153" />
            </geometry>
        </collision>
    </link>
    <link name="Link5">
        <inertial>
            <origin xyz="0.0 0.4448074841793651 0.0" rpy="0 0 0"/>
            <mass value="1.0" />
            <inertia ixx="100" ixy="0" ixz="0" iyy="100" iyz="0" izz="100" />
        </inertial>
        <visual>
            <origin xyz="0.0 0.4448074841793651 0.0" rpy="0 0 0"/>
            <geometry>
                <box size="0.8380240053020462 0.8896149683587302 0.454751435769134" />
            </geometry>
            <material name="Blue">
            <color rgba="0.164 0.776 0.95 1.0"/>
            </material>
        </visual>
        <collision>
            <origin xyz="0.0 0.4448074841793651 0.0" rpy="0 0 0"/>
            <geometry>
                <box size="0.8380240053020462 0.8896149683587302 0.454751435769134" />
            </geometry>
        </collision>
    </link>
    <link name="Link6">
        <inertial>
            <origin xyz="0.0 0.0 0.36167766377410926" rpy="0 0 0"/>
            <mass value="1.0" />
            <inertia ixx="100" ixy="0" ixz="0" iyy="100" iyz="0" izz="100" />
        </inertial>
        <visual>
            <origin xyz="0.0 0.0 0.36167766377410926" rpy="0 0 0"/>
            <geometry>
                <box size="0.4468470894606987 0.5189294489576445 0.7233553275482185" />
            </geometry>
            <material name="Green">
            <color rgba="0.164 0.776 0.478 1.0"/>
            </material>
        </visual>
        <collision>
            <origin xyz="0.0 0.0 0.36167766377410926" rpy="0 0 0"/>
            <geometry>
                <box size="0.4468470894606987 0.5189294489576445 0.7233553275482185" />
            </geometry>
        </collision>
    </link>
    <link name="Link7">
        <inertial>
            <origin xyz="0.18529099623983267 0.0 0.0" rpy="0 0 0"/>
            <mass value="1.0" />
            <inertia ixx="100" ixy="0" ixz="0" iyy="100" iyz="0" izz="100" />
        </inertial>
        <visual>
            <origin xyz="0.18529099623983267 0.0 0.0" rpy="0 0 0"/>
            <geometry>
                <box size="0.37058199247966533 0.40574128127010767 0.39531140016654476" />
            </geometry>
            <material name="Blue">
            <color rgba="0.164 0.776 0.95 1.0"/>
            </material>
        </visual>
        <collision>
            <origin xyz="0.18529099623983267 0.0 0.0" rpy="0 0 0"/>
            <geometry>
                <box size="0.37058199247966533 0.40574128127010767 0.39531140016654476" />
            </geometry>
        </collision>
    </link>
    <link name="Link8">
        <inertial>
            <origin xyz="0.0 0.15532644465026613 0.0" rpy="0 0 0"/>
            <mass value="1.0" />
            <inertia ixx="100" ixy="0" ixz="0" iyy="100" iyz="0" izz="100" />
        </inertial>
        <visual>
            <origin xyz="0.0 0.15532644465026613 0.0" rpy="0 0 0"/>
            <geometry>
                <box size="0.7545662001117566 0.31065288930053225 0.4219036335513147" />
            </geometry>
            <material name="Blue">
            <color rgba="0.164 0.776 0.95 1.0"/>
            </material>
        </visual>
        <collision>
            <origin xyz="0.0 0.15532644465026613 0.0" rpy="0 0 0"/>
            <geometry>
                <box size="0.7545662001117566 0.31065288930053225 0.4219036335513147" />
            </geometry>
        </collision>
    </link>
    <link name="Link9">
        <inertial>
            <origin xyz="0.0 0.0 -0.15230793367057197" rpy="0 0 0"/>
            <mass value="1.0" />
            <inertia ixx="100" ixy="0" ixz="0" iyy="100" iyz="0" izz="100" />
        </inertial>
        <visual>
            <origin xyz="0.0 0.0 -0.15230793367057197" rpy="0 0 0"/>
            <geometry>
                <box size="0.3420828802284942 0.3181374565564467 0.30461586734114393" />
            </geometry>
            <material name="Green">
            <color rgba="0.164 0.776 0.478 1.0"/>
            </material>
        </visual>
        <collision>
            <origin xyz="0.0 0.0 -0.15230793367057197" rpy="0 0 0"/>
            <geometry>
                <box size="0.3420828802284942 0.3181374565564467 0.30461586734114393" />
            </geometry>
        </collision>
    </link>
    <link name="Link10">
        <inertial>
            <origin xyz="0.0 0.0 0.20683491558663847" rpy="0 0 0"/>
            <mass value="1.0" />
            <inertia ixx="100" ixy="0" ixz="0" iyy="100" iyz="0" izz="100" />
        </inertial>
        <visual>
            <origin xyz="0.0 0.0 0.20683491558663847" rpy="0 0 0"/>
            <geometry>
                <box size="0.6882562220540407 0.5171873036407506 0.41366983117327694" />
            </geometry>
            <material name="Green">
            <color rgba="0.164 0.776 0.478 1.0"/>
            </material>
        </visual>
        <collision>
            <origin xyz="0.0 0.0 0.20683491558663847" rpy="0 0 0"/>
            <geometry>
                <box size="0.6882562220540407 0.5171873036407506 0.41366983117327694" />
            </geometry>
        </collision>
    </link>
    <link name="Link11">
        <inertial>
            <origin xyz="0.0 0.20769306972157653 0.0" rpy="0 0 0"/>
            <mass value="1.0" />
            <inertia ixx="100" ixy="0" ixz="0" iyy="100" iyz="0" izz="100" />
        </inertial>
        <visual>
            <origin xyz="0.0 0.20769306972157653 0.0" rpy="0 0 0"/>
            <geometry>
                <box size="0.6797595243944003 0.41538613944315306 0.3721167354339261" />
            </geometry>
            <material name="Green">
            <color rgba="0.164 0.776 0.478 1.0"/>
            </material>
        </visual>
        <collision>
            <origin xyz="0.0 0.20769306972157653 0.0" rpy="0 0 0"/>
            <geometry>
                <box size="0.6797595243944003 0.41538613944315306 0.3721167354339261" />
            </geometry>
        </collision>
    </link>
    <joint name="Link0_Link1" type="revolute">
       <parent link="Link0"/>
       <child  link="Link1"/>
       <origin rpy="0 0 0" xyz="0.0 0.0 3.5" />
     <axis xyz="0 0 1"/>
       <limit effort="0.0" lower="-3.14159" upper="3.14159" velocity="0.0"/>
    </joint>
    <joint name="Link0_Link2" type="revolute">
       <parent link="Link0"/>
       <child  link="Link2"/>
       <origin rpy="0 0 0" xyz="0.0 -0.5 3.0" />
     <axis xyz="1 0 0"/>
       <limit effort="0.0" lower="-3.14159" upper="3.14159" velocity="0.0"/>
    </joint>
    <joint name="Link1_Link3" type="revolute">
       <parent link="Link1"/>
       <child  link="Link3"/>
       <origin rpy="0 0 0" xyz="0.4283177479479938 0.0 0.40896450115897576" />
     <axis xyz="1 0 0"/>
       <limit effort="0.0" lower="-3.14159" upper="3.14159" velocity="0.0"/>
    </joint>
    <joint name="Link3_Link4" type="revolute">
       <parent link="Link3"/>
       <child  link="Link4"/>
       <origin rpy="0 0 0" xyz="0.20067488869876748 0.43613797434558665 0.0" />
     <axis xyz="0 0 1"/>
       <limit effort="0.0" lower="-3.14159" upper="3.14159" velocity="0.0"/>
    </joint>
    <joint name="Link1_Link5" type="revolute">
       <parent link="Link1"/>
       <child  link="Link5"/>
       <origin rpy="0 0 0" xyz="0.0 0.4798575993219676 0.40896450115897576" />
     <axis xyz="0 1 0"/>
       <limit effort="0.0" lower="-3.14159" upper="3.14159" velocity="0.0"/>
    </joint>
    <joint name="Link1_Link6" type="revolute">
       <parent link="Link1"/>
       <child  link="Link6"/>
       <origin rpy="0 0 0" xyz="0.0 0.0 0.8179290023179515" />
     <axis xyz="0 1 0"/>
       <limit effort="0.0" lower="-3.14159" upper="3.14159" velocity="0.0"/>
    </joint>
    <joint name="Link3_Link7" type="revolute">
       <parent link="Link3"/>
       <child  link="Link7"/>
       <origin rpy="0 0 0" xyz="0.40134977739753497 0.0 0.0" />
     <axis xyz="0 0 1"/>
       <limit effort="0.0" lower="-3.14159" upper="3.14159" velocity="0.0"/>
    </joint>
    <joint name="Link5_Link8" type="revolute">
       <parent link="Link5"/>
       <child  link="Link8"/>
       <origin rpy="0 0 0" xyz="0.0 0.8896149683587302 0.0" />
     <axis xyz="0 1 0"/>
       <limit effort="0.0" lower="-3.14159" upper="3.14159" velocity="0.0"/>
    </joint>
    <joint name="Link7_Link9" type="revolute">
       <parent link="Link7"/>
       <child  link="Link9"/>
       <origin rpy="0 0 0" xyz="0.1852909962398328 0.0 -0.19765570008327238" />
     <axis xyz="0 0 1"/>
       <limit effort="0.0" lower="-3.14159" upper="3.14159" velocity="0.0"/>
    </joint>
    <joint name="Link5_Link10" type="revolute">
       <parent link="Link5"/>
       <child  link="Link10"/>
       <origin rpy="0 0 0" xyz="0.0 0.4448074841793651 0.22737571788456723" />
     <axis xyz="0 0 1"/>
       <limit effort="0.0" lower="-3.14159" upper="3.14159" velocity="0.0"/>
    </joint>
    <joint name="Link10_Link11" type="revolute">
       <parent link="Link10"/>
       <child  link="Link11"/>
       <origin rpy="0 0 0" xyz="0.0 0.2585936518203752 0.20683491558663825" />
     <axis xyz="0 1 0"/>
       <limit effort="0.0" lower="-3.14159" upper="3.14159" velocity="0.0"/>
    </joint>
</robot>