<robot name = "robot">
    <link name="Link0">
        <inertial>
            <origin xyz="0 0 3" rpy="0 0 0"/>
            <mass value="1.0" />
            <inertia ixx="100" ixy="0" ixz="0" iyy="100" iyz="0" izz="100" />
        </inertial>
        <visual>
            <origin xyz="0 0 3" rpy="0 0 0"/>
            <geometry>
                <box size="1 1 1" />
            </geometry>
            <material name="Green">
            <color rgba="0.164 0.776 0.478 1.0"/>
            </material>
        </visual>
        <collision>
            <origin xyz="0 0 3" rpy="0 0 0"/>
            <geometry>
                <box size="1 1 1" />
            </geometry>
        </collision>
    </link>
    <link name="Link1">
        <inertial>
            <origin xyz="0.0 0.0 0.3396180798608332" rpy="0 0 0"/>
            <mass value="1.0" />
            <inertia ixx="100" ixy="0" ixz="0" iyy="100" iyz="0" izz="100" />
        </inertial>
        <visual>
            <origin xyz="0.0 0.0 0.3396180798608332" rpy="0 0 0"/>
            <geometry>
                <box size="0.7890311092320552 0.5284732019546856 0.6792361597216664" />
            </geometry>
            <material name="Green">
            <color rgba="0.164 0.776 0.478 1.0"/>
            </material>
        </visual>
        <collision>
            <origin xyz="0.0 0.0 0.3396180798608332" rpy="0 0 0"/>
            <geometry>
                <box size="0.7890311092320552 0.5284732019546856 0.6792361597216664" />
            </geometry>
        </collision>
    </link>
    <link name="Link2">
        <inertial>
            <origin xyz="0.37154156670766153 0.0 0.0" rpy="0 0 0"/>
            <mass value="1.0" />
            <inertia ixx="100" ixy="0" ixz="0" iyy="100" iyz="0" izz="100" />
        </inertial>
        <visual>
            <origin xyz="0.37154156670766153 0.0 0.0" rpy="0 0 0"/>
            <geometry>
                <box size="0.7430831334153231 0.9916504241635846 0.48695943429671384" />
            </geometry>
            <material name="Green">
            <color rgba="0.164 0.776 0.478 1.0"/>
            </material>
        </visual>
        <collision>
            <origin xyz="0.37154156670766153 0.0 0.0" rpy="0 0 0"/>
            <geometry>
                <box size="0.7430831334153231 0.9916504241635846 0.48695943429671384" />
            </geometry>
        </collision>
    </link>
    <link name="Link3">
        <inertial>
            <origin xyz="0.0 0.35523128409559984 0.0" rpy="0 0 0"/>
            <mass value="1.0" />
            <inertia ixx="100" ixy="0" ixz="0" iyy="100" iyz="0" izz="100" />
        </inertial>
        <visual>
            <origin xyz="0.0 0.35523128409559984 0.0" rpy="0 0 0"/>
            <geometry>
                <box size="0.564463338277551 0.7104625681911997 0.6855960087227353" />
            </geometry>
            <material name="Green">
            <color rgba="0.164 0.776 0.478 1.0"/>
            </material>
        </visual>
        <collision>
            <origin xyz="0.0 0.35523128409559984 0.0" rpy="0 0 0"/>
            <geometry>
                <box size="0.564463338277551 0.7104625681911997 0.6855960087227353" />
            </geometry>
        </collision>
    </link>
    <link name="Link4">
        <inertial>
            <origin xyz="0.0 0.18739038191600704 0.0" rpy="0 0 0"/>
            <mass value="1.0" />
            <inertia ixx="100" ixy="0" ixz="0" iyy="100" iyz="0" izz="100" />
        </inertial>
        <visual>
            <origin xyz="0.0 0.18739038191600704 0.0" rpy="0 0 0"/>
            <geometry>
                <box size="0.3032047022862867 0.3747807638320141 0.40013139152827304" />
            </geometry>
            <material name="Blue">
            <color rgba="0.164 0.776 0.95 1.0"/>
            </material>
        </visual>
        <collision>
            <origin xyz="0.0 0.18739038191600704 0.0" rpy="0 0 0"/>
            <geometry>
                <box size="0.3032047022862867 0.3747807638320141 0.40013139152827304" />
            </geometry>
        </collision>
    </link>
    <link name="Link5">
        <inertial>
            <origin xyz="0.0 0.3496660978112772 0.0" rpy="0 0 0"/>
            <mass value="1.0" />
            <inertia ixx="100" ixy="0" ixz="0" iyy="100" iyz="0" izz="100" />
        </inertial>
        <visual>
            <origin xyz="0.0 0.3496660978112772 0.0" rpy="0 0 0"/>
            <geometry>
                <box size="0.3271267519014437 0.6993321956225544 0.612915801510049" />
            </geometry>
            <material name="Blue">
            <color rgba="0.164 0.776 0.95 1.0"/>
            </material>
        </visual>
        <collision>
            <origin xyz="0.0 0.3496660978112772 0.0" rpy="0 0 0"/>
            <geometry>
                <box size="0.3271267519014437 0.6993321956225544 0.612915801510049" />
            </geometry>
        </collision>
    </link>
    <link name="Link6">
        <inertial>
            <origin xyz="0.0 0.0 -0.1676520119663702" rpy="0 0 0"/>
            <mass value="1.0" />
            <inertia ixx="100" ixy="0" ixz="0" iyy="100" iyz="0" izz="100" />
        </inertial>
        <visual>
            <origin xyz="0.0 0.0 -0.1676520119663702" rpy="0 0 0"/>
            <geometry>
                <box size="0.3014941938180312 0.3507971818021681 0.3353040239327404" />
            </geometry>
            <material name="Blue">
            <color rgba="0.164 0.776 0.95 1.0"/>
            </material>
        </visual>
        <collision>
            <origin xyz="0.0 0.0 -0.1676520119663702" rpy="0 0 0"/>
            <geometry>
                <box size="0.3014941938180312 0.3507971818021681 0.3353040239327404" />
            </geometry>
        </collision>
    </link>
    <link name="Link7">
        <inertial>
            <origin xyz="0.0 0.16209513400183628 0.0" rpy="0 0 0"/>
            <mass value="1.0" />
            <inertia ixx="100" ixy="0" ixz="0" iyy="100" iyz="0" izz="100" />
        </inertial>
        <visual>
            <origin xyz="0.0 0.16209513400183628 0.0" rpy="0 0 0"/>
            <geometry>
                <box size="0.3006017383328752 0.32419026800367257 0.5115374369803138" />
            </geometry>
            <material name="Blue">
            <color rgba="0.164 0.776 0.95 1.0"/>
            </material>
        </visual>
        <collision>
            <origin xyz="0.0 0.16209513400183628 0.0" rpy="0 0 0"/>
            <geometry>
                <box size="0.3006017383328752 0.32419026800367257 0.5115374369803138" />
            </geometry>
        </collision>
    </link>
    <link name="Link8">
        <inertial>
            <origin xyz="0.15007866902604047 0.0 0.0" rpy="0 0 0"/>
            <mass value="1.0" />
            <inertia ixx="100" ixy="0" ixz="0" iyy="100" iyz="0" izz="100" />
        </inertial>
        <visual>
            <origin xyz="0.15007866902604047 0.0 0.0" rpy="0 0 0"/>
            <geometry>
                <box size="0.30015733805208095 0.3238706989666889 0.3526168372966615" />
            </geometry>
            <material name="Blue">
            <color rgba="0.164 0.776 0.95 1.0"/>
            </material>
        </visual>
        <collision>
            <origin xyz="0.15007866902604047 0.0 0.0" rpy="0 0 0"/>
            <geometry>
                <box size="0.30015733805208095 0.3238706989666889 0.3526168372966615" />
            </geometry>
        </collision>
    </link>
    <link name="Link9">
        <inertial>
            <origin xyz="-0.1502918399561867 0.0 0.0" rpy="0 0 0"/>
            <mass value="1.0" />
            <inertia ixx="100" ixy="0" ixz="0" iyy="100" iyz="0" izz="100" />
        </inertial>
        <visual>
            <origin xyz="-0.1502918399561867 0.0 0.0" rpy="0 0 0"/>
            <geometry>
                <box size="0.3005836799123734 0.3241905053213411 0.3219533262125164" />
            </geometry>
            <material name="Green">
            <color rgba="0.164 0.776 0.478 1.0"/>
            </material>
        </visual>
        <collision>
            <origin xyz="-0.1502918399561867 0.0 0.0" rpy="0 0 0"/>
            <geometry>
                <box size="0.3005836799123734 0.3241905053213411 0.3219533262125164" />
            </geometry>
        </collision>
    </link>
    <link name="Link10">
        <inertial>
            <origin xyz="0.0 0.0 0.17761678048921659" rpy="0 0 0"/>
            <mass value="1.0" />
            <inertia ixx="100" ixy="0" ixz="0" iyy="100" iyz="0" izz="100" />
        </inertial>
        <visual>
            <origin xyz="0.0 0.0 0.17761678048921659" rpy="0 0 0"/>
            <geometry>
                <box size="0.3000378428667973 0.35509394140761164 0.35523356097843317" />
            </geometry>
            <material name="Green">
            <color rgba="0.164 0.776 0.478 1.0"/>
            </material>
        </visual>
        <collision>
            <origin xyz="0.0 0.0 0.17761678048921659" rpy="0 0 0"/>
            <geometry>
                <box size="0.3000378428667973 0.35509394140761164 0.35523356097843317" />
            </geometry>
        </collision>
    </link>
    <joint name="Link0_Link1" type="revolute">
       <parent link="Link0"/>
       <child  link="Link1"/>
       <origin rpy="0 0 0" xyz="0.0 0.0 3.5" />
     <axis xyz="1 0 0"/>
       <limit effort="0.0" lower="-3.14159" upper="3.14159" velocity="0.0"/>
    </joint>
    <joint name="Link0_Link2" type="revolute">
       <parent link="Link0"/>
       <child  link="Link2"/>
       <origin rpy="0 0 0" xyz="0.5 0.0 3.0" />
     <axis xyz="0 0 1"/>
       <limit effort="0.0" lower="-3.14159" upper="3.14159" velocity="0.0"/>
    </joint>
    <joint name="Link0_Link3" type="revolute">
       <parent link="Link0"/>
       <child  link="Link3"/>
       <origin rpy="0 0 0" xyz="0.0 0.5 3.0" />
     <axis xyz="1 0 0"/>
       <limit effort="0.0" lower="-3.14159" upper="3.14159" velocity="0.0"/>
    </joint>
    <joint name="Link2_Link4" type="revolute">
       <parent link="Link2"/>
       <child  link="Link4"/>
       <origin rpy="0 0 0" xyz="0.3715415667076616 0.4958252120817923 0.0" />
     <axis xyz="0 1 0"/>
       <limit effort="0.0" lower="-3.14159" upper="3.14159" velocity="0.0"/>
    </joint>
    <joint name="Link3_Link5" type="revolute">
       <parent link="Link3"/>
       <child  link="Link5"/>
       <origin rpy="0 0 0" xyz="0.0 0.7104625681911996 0.0" />
     <axis xyz="1 0 0"/>
       <limit effort="0.0" lower="-3.14159" upper="3.14159" velocity="0.0"/>
    </joint>
    <joint name="Link4_Link6" type="revolute">
       <parent link="Link4"/>
       <child  link="Link6"/>
       <origin rpy="0 0 0" xyz="0.0 0.187390381916007 -0.20006569576413646" />
     <axis xyz="0 0 1"/>
       <limit effort="0.0" lower="-3.14159" upper="3.14159" velocity="0.0"/>
    </joint>
    <joint name="Link5_Link7" type="revolute">
       <parent link="Link5"/>
       <child  link="Link7"/>
       <origin rpy="0 0 0" xyz="0.0 0.6993321956225547 0.0" />
     <axis xyz="0 0 1"/>
       <limit effort="0.0" lower="-3.14159" upper="3.14159" velocity="0.0"/>
    </joint>
    <joint name="Link7_Link8" type="revolute">
       <parent link="Link7"/>
       <child  link="Link8"/>
       <origin rpy="0 0 0" xyz="0.1503008691664376 0.16209513400183617 0.0" />
     <axis xyz="0 0 1"/>
       <limit effort="0.0" lower="-3.14159" upper="3.14159" velocity="0.0"/>
    </joint>
    <joint name="Link6_Link9" type="revolute">
       <parent link="Link6"/>
       <child  link="Link9"/>
       <origin rpy="0 0 0" xyz="-0.15074709690901567 0.0 -0.16765201196637047" />
     <axis xyz="0 0 1"/>
       <limit effort="0.0" lower="-3.14159" upper="3.14159" velocity="0.0"/>
    </joint>
    <joint name="Link4_Link10" type="revolute">
       <parent link="Link4"/>
       <child  link="Link10"/>
       <origin rpy="0 0 0" xyz="0.0 0.187390381916007 0.20006569576413646" />
     <axis xyz="0 0 1"/>
       <limit effort="0.0" lower="-3.14159" upper="3.14159" velocity="0.0"/>
    </joint>
</robot>