<robot name = "robot">
    <link name="Link0">
        <inertial>
            <origin xyz="0 0 3" rpy="0 0 0"/>
            <mass value="1.0" />
            <inertia ixx="100" ixy="0" ixz="0" iyy="100" iyz="0" izz="100" />
        </inertial>
        <visual>
            <origin xyz="0 0 3" rpy="0 0 0"/>
            <geometry>
                <box size="1 1 1" />
            </geometry>
            <material name="Blue">
            <color rgba="0.164 0.776 0.95 1.0"/>
            </material>
        </visual>
        <collision>
            <origin xyz="0 0 3" rpy="0 0 0"/>
            <geometry>
                <box size="1 1 1" />
            </geometry>
        </collision>
    </link>
    <link name="Link1">
        <inertial>
            <origin xyz="0.0 0.0 0.15693601176557578" rpy="0 0 0"/>
            <mass value="1.0" />
            <inertia ixx="100" ixy="0" ixz="0" iyy="100" iyz="0" izz="100" />
        </inertial>
        <visual>
            <origin xyz="0.0 0.0 0.15693601176557578" rpy="0 0 0"/>
            <geometry>
                <box size="0.6352148764467282 0.363070170928244 0.31387202353115157" />
            </geometry>
            <material name="Blue">
            <color rgba="0.164 0.776 0.95 1.0"/>
            </material>
        </visual>
        <collision>
            <origin xyz="0.0 0.0 0.15693601176557578" rpy="0 0 0"/>
            <geometry>
                <box size="0.6352148764467282 0.363070170928244 0.31387202353115157" />
            </geometry>
        </collision>
    </link>
    <link name="Link2">
        <inertial>
            <origin xyz="0.3321187443125099 0.0 0.0" rpy="0 0 0"/>
            <mass value="1.0" />
            <inertia ixx="100" ixy="0" ixz="0" iyy="100" iyz="0" izz="100" />
        </inertial>
        <visual>
            <origin xyz="0.3321187443125099 0.0 0.0" rpy="0 0 0"/>
            <geometry>
                <box size="0.6642374886250197 0.5521714366501409 0.8458218851749983" />
            </geometry>
            <material name="Green">
            <color rgba="0.164 0.776 0.478 1.0"/>
            </material>
        </visual>
        <collision>
            <origin xyz="0.3321187443125099 0.0 0.0" rpy="0 0 0"/>
            <geometry>
                <box size="0.6642374886250197 0.5521714366501409 0.8458218851749983" />
            </geometry>
        </collision>
    </link>
    <link name="Link3">
        <inertial>
            <origin xyz="-0.4401220170724468 0.0 0.0" rpy="0 0 0"/>
            <mass value="1.0" />
            <inertia ixx="100" ixy="0" ixz="0" iyy="100" iyz="0" izz="100" />
        </inertial>
        <visual>
            <origin xyz="-0.4401220170724468 0.0 0.0" rpy="0 0 0"/>
            <geometry>
                <box size="0.8802440341448936 0.8646566426916265 0.8603134869800764" />
            </geometry>
            <material name="Green">
            <color rgba="0.164 0.776 0.478 1.0"/>
            </material>
        </visual>
        <collision>
            <origin xyz="-0.4401220170724468 0.0 0.0" rpy="0 0 0"/>
            <geometry>
                <box size="0.8802440341448936 0.8646566426916265 0.8603134869800764" />
            </geometry>
        </collision>
    </link>
    <link name="Link4">
        <inertial>
            <origin xyz="0.0 0.24228147010729148 0.0" rpy="0 0 0"/>
            <mass value="1.0" />
            <inertia ixx="100" ixy="0" ixz="0" iyy="100" iyz="0" izz="100" />
        </inertial>
        <visual>
            <origin xyz="0.0 0.24228147010729148 0.0" rpy="0 0 0"/>
            <geometry>
                <box size="0.5283680188521174 0.48456294021458296 0.766485777920554" />
            </geometry>
            <material name="Blue">
            <color rgba="0.164 0.776 0.95 1.0"/>
            </material>
        </visual>
        <collision>
            <origin xyz="0.0 0.24228147010729148 0.0" rpy="0 0 0"/>
            <geometry>
                <box size="0.5283680188521174 0.48456294021458296 0.766485777920554" />
            </geometry>
        </collision>
    </link>
    <link name="Link5">
        <inertial>
            <origin xyz="0.0 0.0 -0.31129961280957114" rpy="0 0 0"/>
            <mass value="1.0" />
            <inertia ixx="100" ixy="0" ixz="0" iyy="100" iyz="0" izz="100" />
        </inertial>
        <visual>
            <origin xyz="0.0 0.0 -0.31129961280957114" rpy="0 0 0"/>
            <geometry>
                <box size="0.5108843207048654 0.5023116433448901 0.6225992256191423" />
            </geometry>
            <material name="Blue">
            <color rgba="0.164 0.776 0.95 1.0"/>
            </material>
        </visual>
        <collision>
            <origin xyz="0.0 0.0 -0.31129961280957114" rpy="0 0 0"/>
            <geometry>
                <box size="0.5108843207048654 0.5023116433448901 0.6225992256191423" />
            </geometry>
        </collision>
    </link>
    <link name="Link6">
        <inertial>
            <origin xyz="0.0 -0.3872153618052724 0.0" rpy="0 0 0"/>
            <mass value="1.0" />
            <inertia ixx="100" ixy="0" ixz="0" iyy="100" iyz="0" izz="100" />
        </inertial>
        <visual>
            <origin xyz="0.0 -0.3872153618052724 0.0" rpy="0 0 0"/>
            <geometry>
                <box size="0.5572081249029261 0.7744307236105448 0.6845708654274234" />
            </geometry>
            <material name="Blue">
            <color rgba="0.164 0.776 0.95 1.0"/>
            </material>
        </visual>
        <collision>
            <origin xyz="0.0 -0.3872153618052724 0.0" rpy="0 0 0"/>
            <geometry>
                <box size="0.5572081249029261 0.7744307236105448 0.6845708654274234" />
            </geometry>
        </collision>
    </link>
    <joint name="Link0_Link1" type="revolute">
       <parent link="Link0"/>
       <child  link="Link1"/>
       <origin rpy="0 0 0" xyz="0.0 0.0 3.5" />
     <axis xyz="0 1 0"/>
       <limit effort="0.0" lower="-3.14159" upper="3.14159" velocity="0.0"/>
    </joint>
    <joint name="Link0_Link2" type="revolute">
       <parent link="Link0"/>
       <child  link="Link2"/>
       <origin rpy="0 0 0" xyz="0.5 0.0 3.0" />
     <axis xyz="0 1 0"/>
       <limit effort="0.0" lower="-3.14159" upper="3.14159" velocity="0.0"/>
    </joint>
    <joint name="Link0_Link3" type="revolute">
       <parent link="Link0"/>
       <child  link="Link3"/>
       <origin rpy="0 0 0" xyz="-0.5 0.0 3.0" />
     <axis xyz="0 1 0"/>
       <limit effort="0.0" lower="-3.14159" upper="3.14159" velocity="0.0"/>
    </joint>
    <joint name="Link2_Link4" type="revolute">
       <parent link="Link2"/>
       <child  link="Link4"/>
       <origin rpy="0 0 0" xyz="0.3321187443125099 0.27608571832507045 0.0" />
     <axis xyz="1 0 0"/>
       <limit effort="0.0" lower="-3.14159" upper="3.14159" velocity="0.0"/>
    </joint>
    <joint name="Link2_Link5" type="revolute">
       <parent link="Link2"/>
       <child  link="Link5"/>
       <origin rpy="0 0 0" xyz="0.3321187443125099 0.0 -0.42291094258749906" />
     <axis xyz="0 1 0"/>
       <limit effort="0.0" lower="-3.14159" upper="3.14159" velocity="0.0"/>
    </joint>
    <joint name="Link0_Link6" type="revolute">
       <parent link="Link0"/>
       <child  link="Link6"/>
       <origin rpy="0 0 0" xyz="0.0 -0.5 3.0" />
     <axis xyz="0 1 0"/>
       <limit effort="0.0" lower="-3.14159" upper="3.14159" velocity="0.0"/>
    </joint>
</robot>