<robot name = "robot">
    <link name="Link0">
        <inertial>
            <origin xyz="0 0 3" rpy="0 0 0"/>
            <mass value="1.0" />
            <inertia ixx="100" ixy="0" ixz="0" iyy="100" iyz="0" izz="100" />
        </inertial>
        <visual>
            <origin xyz="0 0 3" rpy="0 0 0"/>
            <geometry>
                <box size="1 1 1" />
            </geometry>
            <material name="Green">
            <color rgba="0.164 0.776 0.478 1.0"/>
            </material>
        </visual>
        <collision>
            <origin xyz="0 0 3" rpy="0 0 0"/>
            <geometry>
                <box size="1 1 1" />
            </geometry>
        </collision>
    </link>
    <link name="Link1">
        <inertial>
            <origin xyz="0.3037643696636857 0.0 0.0" rpy="0 0 0"/>
            <mass value="1.0" />
            <inertia ixx="100" ixy="0" ixz="0" iyy="100" iyz="0" izz="100" />
        </inertial>
        <visual>
            <origin xyz="0.3037643696636857 0.0 0.0" rpy="0 0 0"/>
            <geometry>
                <box size="0.6075287393273714 0.445065707689276 0.9415708642120793" />
            </geometry>
            <material name="Green">
            <color rgba="0.164 0.776 0.478 1.0"/>
            </material>
        </visual>
        <collision>
            <origin xyz="0.3037643696636857 0.0 0.0" rpy="0 0 0"/>
            <geometry>
                <box size="0.6075287393273714 0.445065707689276 0.9415708642120793" />
            </geometry>
        </collision>
    </link>
    <link name="Link2">
        <inertial>
            <origin xyz="0.0 0.0 0.4897165827630027" rpy="0 0 0"/>
            <mass value="1.0" />
            <inertia ixx="100" ixy="0" ixz="0" iyy="100" iyz="0" izz="100" />
        </inertial>
        <visual>
            <origin xyz="0.0 0.0 0.4897165827630027" rpy="0 0 0"/>
            <geometry>
                <box size="0.8159849935626178 0.7168743854297621 0.9794331655260053" />
            </geometry>
            <material name="Green">
            <color rgba="0.164 0.776 0.478 1.0"/>
            </material>
        </visual>
        <collision>
            <origin xyz="0.0 0.0 0.4897165827630027" rpy="0 0 0"/>
            <geometry>
                <box size="0.8159849935626178 0.7168743854297621 0.9794331655260053" />
            </geometry>
        </collision>
    </link>
    <link name="Link3">
        <inertial>
            <origin xyz="0.0 -0.17968923702613188 0.0" rpy="0 0 0"/>
            <mass value="1.0" />
            <inertia ixx="100" ixy="0" ixz="0" iyy="100" iyz="0" izz="100" />
        </inertial>
        <visual>
            <origin xyz="0.0 -0.17968923702613188 0.0" rpy="0 0 0"/>
            <geometry>
                <box size="0.5379633167831528 0.35937847405226375 0.9336522017680977" />
            </geometry>
            <material name="Green">
            <color rgba="0.164 0.776 0.478 1.0"/>
            </material>
        </visual>
        <collision>
            <origin xyz="0.0 -0.17968923702613188 0.0" rpy="0 0 0"/>
            <geometry>
                <box size="0.5379633167831528 0.35937847405226375 0.9336522017680977" />
            </geometry>
        </collision>
    </link>
    <link name="Link4">
        <inertial>
            <origin xyz="-0.2559375210806567 0.0 0.0" rpy="0 0 0"/>
            <mass value="1.0" />
            <inertia ixx="100" ixy="0" ixz="0" iyy="100" iyz="0" izz="100" />
        </inertial>
        <visual>
            <origin xyz="-0.2559375210806567 0.0 0.0" rpy="0 0 0"/>
            <geometry>
                <box size="0.5118750421613134 0.31536981876098763 0.5861914912831463" />
            </geometry>
            <material name="Blue">
            <color rgba="0.164 0.776 0.95 1.0"/>
            </material>
        </visual>
        <collision>
            <origin xyz="-0.2559375210806567 0.0 0.0" rpy="0 0 0"/>
            <geometry>
                <box size="0.5118750421613134 0.31536981876098763 0.5861914912831463" />
            </geometry>
        </collision>
    </link>
    <link name="Link5">
        <inertial>
            <origin xyz="0.0 0.0 0.23607989432978638" rpy="0 0 0"/>
            <mass value="1.0" />
            <inertia ixx="100" ixy="0" ixz="0" iyy="100" iyz="0" izz="100" />
        </inertial>
        <visual>
            <origin xyz="0.0 0.0 0.23607989432978638" rpy="0 0 0"/>
            <geometry>
                <box size="0.3968555904613253 0.31534346483230763 0.47215978865957275" />
            </geometry>
            <material name="Green">
            <color rgba="0.164 0.776 0.478 1.0"/>
            </material>
        </visual>
        <collision>
            <origin xyz="0.0 0.0 0.23607989432978638" rpy="0 0 0"/>
            <geometry>
                <box size="0.3968555904613253 0.31534346483230763 0.47215978865957275" />
            </geometry>
        </collision>
    </link>
    <link name="Link6">
        <inertial>
            <origin xyz="0.0 0.17953591867879742 0.0" rpy="0 0 0"/>
            <mass value="1.0" />
            <inertia ixx="100" ixy="0" ixz="0" iyy="100" iyz="0" izz="100" />
        </inertial>
        <visual>
            <origin xyz="0.0 0.17953591867879742 0.0" rpy="0 0 0"/>
            <geometry>
                <box size="0.748757059030706 0.35907183735759485 0.3348370693631625" />
            </geometry>
            <material name="Green">
            <color rgba="0.164 0.776 0.478 1.0"/>
            </material>
        </visual>
        <collision>
            <origin xyz="0.0 0.17953591867879742 0.0" rpy="0 0 0"/>
            <geometry>
                <box size="0.748757059030706 0.35907183735759485 0.3348370693631625" />
            </geometry>
        </collision>
    </link>
    <link name="Link7">
        <inertial>
            <origin xyz="0.19662411252599654 0.0 0.0" rpy="0 0 0"/>
            <mass value="1.0" />
            <inertia ixx="100" ixy="0" ixz="0" iyy="100" iyz="0" izz="100" />
        </inertial>
        <visual>
            <origin xyz="0.19662411252599654 0.0 0.0" rpy="0 0 0"/>
            <geometry>
                <box size="0.3932482250519931 0.3100187832265527 0.4499336347503867" />
            </geometry>
            <material name="Blue">
            <color rgba="0.164 0.776 0.95 1.0"/>
            </material>
        </visual>
        <collision>
            <origin xyz="0.19662411252599654 0.0 0.0" rpy="0 0 0"/>
            <geometry>
                <box size="0.3932482250519931 0.3100187832265527 0.4499336347503867" />
            </geometry>
        </collision>
    </link>
    <link name="Link8">
        <inertial>
            <origin xyz="0.3134799563178714 0.0 0.0" rpy="0 0 0"/>
            <mass value="1.0" />
            <inertia ixx="100" ixy="0" ixz="0" iyy="100" iyz="0" izz="100" />
        </inertial>
        <visual>
            <origin xyz="0.3134799563178714 0.0 0.0" rpy="0 0 0"/>
            <geometry>
                <box size="0.6269599126357428 0.655061441749055 0.5515684023663325" />
            </geometry>
            <material name="Green">
            <color rgba="0.164 0.776 0.478 1.0"/>
            </material>
        </visual>
        <collision>
            <origin xyz="0.3134799563178714 0.0 0.0" rpy="0 0 0"/>
            <geometry>
                <box size="0.6269599126357428 0.655061441749055 0.5515684023663325" />
            </geometry>
        </collision>
    </link>
    <link name="Link9">
        <inertial>
            <origin xyz="0.0 0.0 -0.18906251362671272" rpy="0 0 0"/>
            <mass value="1.0" />
            <inertia ixx="100" ixy="0" ixz="0" iyy="100" iyz="0" izz="100" />
        </inertial>
        <visual>
            <origin xyz="0.0 0.0 -0.18906251362671272" rpy="0 0 0"/>
            <geometry>
                <box size="0.5286500923953682 0.3520262627902769 0.37812502725342545" />
            </geometry>
            <material name="Blue">
            <color rgba="0.164 0.776 0.95 1.0"/>
            </material>
        </visual>
        <collision>
            <origin xyz="0.0 0.0 -0.18906251362671272" rpy="0 0 0"/>
            <geometry>
                <box size="0.5286500923953682 0.3520262627902769 0.37812502725342545" />
            </geometry>
        </collision>
    </link>
    <joint name="Link0_Link1" type="revolute">
       <parent link="Link0"/>
       <child  link="Link1"/>
       <origin rpy="0 0 0" xyz="0.5 0.0 3.0" />
     <axis xyz="0 1 0"/>
       <limit effort="0.0" lower="-3.14159" upper="3.14159" velocity="0.0"/>
    </joint>
    <joint name="Link0_Link2" type="revolute">
       <parent link="Link0"/>
       <child  link="Link2"/>
       <origin rpy="0 0 0" xyz="0.0 0.0 3.5" />
     <axis xyz="0 1 0"/>
       <limit effort="0.0" lower="-3.14159" upper="3.14159" velocity="0.0"/>
    </joint>
    <joint name="Link1_Link3" type="revolute">
       <parent link="Link1"/>
       <child  link="Link3"/>
       <origin rpy="0 0 0" xyz="0.3037643696636857 -0.222532853844638 0.0" />
     <axis xyz="0 0 1"/>
       <limit effort="0.0" lower="-3.14159" upper="3.14159" velocity="0.0"/>
    </joint>
    <joint name="Link2_Link4" type="revolute">
       <parent link="Link2"/>
       <child  link="Link4"/>
       <origin rpy="0 0 0" xyz="-0.4079924967813089 0.0 0.4897165827630028" />
     <axis xyz="0 1 0"/>
       <limit effort="0.0" lower="-3.14159" upper="3.14159" velocity="0.0"/>
    </joint>
    <joint name="Link2_Link5" type="revolute">
       <parent link="Link2"/>
       <child  link="Link5"/>
       <origin rpy="0 0 0" xyz="0.0 0.0 0.9794331655260056" />
     <axis xyz="0 1 0"/>
       <limit effort="0.0" lower="-3.14159" upper="3.14159" velocity="0.0"/>
    </joint>
    <joint name="Link2_Link6" type="revolute">
       <parent link="Link2"/>
       <child  link="Link6"/>
       <origin rpy="0 0 0" xyz="0.0 0.35843719271488106 0.4897165827630028" />
     <axis xyz="0 1 0"/>
       <limit effort="0.0" lower="-3.14159" upper="3.14159" velocity="0.0"/>
    </joint>
    <joint name="Link5_Link7" type="revolute">
       <parent link="Link5"/>
       <child  link="Link7"/>
       <origin rpy="0 0 0" xyz="0.19842779523066265 0.0 0.23607989432978638" />
     <axis xyz="0 0 1"/>
       <limit effort="0.0" lower="-3.14159" upper="3.14159" velocity="0.0"/>
    </joint>
    <joint name="Link2_Link8" type="revolute">
       <parent link="Link2"/>
       <child  link="Link8"/>
       <origin rpy="0 0 0" xyz="0.4079924967813089 0.0 0.4897165827630028" />
     <axis xyz="1 0 0"/>
       <limit effort="0.0" lower="-3.14159" upper="3.14159" velocity="0.0"/>
    </joint>
    <joint name="Link1_Link9" type="revolute">
       <parent link="Link1"/>
       <child  link="Link9"/>
       <origin rpy="0 0 0" xyz="0.3037643696636857 0.0 -0.4707854321060396" />
     <axis xyz="0 0 1"/>
       <limit effort="0.0" lower="-3.14159" upper="3.14159" velocity="0.0"/>
    </joint>
</robot>