<robot name = "robot">
    <link name="Link0">
        <inertial>
            <origin xyz="0 0 3" rpy="0 0 0"/>
            <mass value="1.0" />
            <inertia ixx="100" ixy="0" ixz="0" iyy="100" iyz="0" izz="100" />
        </inertial>
        <visual>
            <origin xyz="0 0 3" rpy="0 0 0"/>
            <geometry>
                <box size="1 1 1" />
            </geometry>
            <material name="Blue">
            <color rgba="0.164 0.776 0.95 1.0"/>
            </material>
        </visual>
        <collision>
            <origin xyz="0 0 3" rpy="0 0 0"/>
            <geometry>
                <box size="1 1 1" />
            </geometry>
        </collision>
    </link>
    <link name="Link1">
        <inertial>
            <origin xyz="0.0 0.0 0.47256122808935475" rpy="0 0 0"/>
            <mass value="1.0" />
            <inertia ixx="100" ixy="0" ixz="0" iyy="100" iyz="0" izz="100" />
        </inertial>
        <visual>
            <origin xyz="0.0 0.0 0.47256122808935475" rpy="0 0 0"/>
            <geometry>
                <box size="0.9806476380861597 0.4536284277866641 0.9451224561787095" />
            </geometry>
            <material name="Blue">
            <color rgba="0.164 0.776 0.95 1.0"/>
            </material>
        </visual>
        <collision>
            <origin xyz="0.0 0.0 0.47256122808935475" rpy="0 0 0"/>
            <geometry>
                <box size="0.9806476380861597 0.4536284277866641 0.9451224561787095" />
            </geometry>
        </collision>
    </link>
    <link name="Link2">
        <inertial>
            <origin xyz="0.0 0.3923949376109851 0.0" rpy="0 0 0"/>
            <mass value="1.0" />
            <inertia ixx="100" ixy="0" ixz="0" iyy="100" iyz="0" izz="100" />
        </inertial>
        <visual>
            <origin xyz="0.0 0.3923949376109851 0.0" rpy="0 0 0"/>
            <geometry>
                <box size="0.5182614222847116 0.7847898752219702 0.8942937857406026" />
            </geometry>
            <material name="Green">
            <color rgba="0.164 0.776 0.478 1.0"/>
            </material>
        </visual>
        <collision>
            <origin xyz="0.0 0.3923949376109851 0.0" rpy="0 0 0"/>
            <geometry>
                <box size="0.5182614222847116 0.7847898752219702 0.8942937857406026" />
            </geometry>
        </collision>
    </link>
    <link name="Link3">
        <inertial>
            <origin xyz="0.0 0.0 0.4044400912638707" rpy="0 0 0"/>
            <mass value="1.0" />
            <inertia ixx="100" ixy="0" ixz="0" iyy="100" iyz="0" izz="100" />
        </inertial>
        <visual>
            <origin xyz="0.0 0.0 0.4044400912638707" rpy="0 0 0"/>
            <geometry>
                <box size="0.4607316655199575 0.5882452998185737 0.8088801825277414" />
            </geometry>
            <material name="Blue">
            <color rgba="0.164 0.776 0.95 1.0"/>
            </material>
        </visual>
        <collision>
            <origin xyz="0.0 0.0 0.4044400912638707" rpy="0 0 0"/>
            <geometry>
                <box size="0.4607316655199575 0.5882452998185737 0.8088801825277414" />
            </geometry>
        </collision>
    </link>
    <link name="Link4">
        <inertial>
            <origin xyz="0.23528358658381182 0.0 0.0" rpy="0 0 0"/>
            <mass value="1.0" />
            <inertia ixx="100" ixy="0" ixz="0" iyy="100" iyz="0" izz="100" />
        </inertial>
        <visual>
            <origin xyz="0.23528358658381182 0.0 0.0" rpy="0 0 0"/>
            <geometry>
                <box size="0.47056717316762364 0.3334324169722621 0.6674084314089178" />
            </geometry>
            <material name="Blue">
            <color rgba="0.164 0.776 0.95 1.0"/>
            </material>
        </visual>
        <collision>
            <origin xyz="0.23528358658381182 0.0 0.0" rpy="0 0 0"/>
            <geometry>
                <box size="0.47056717316762364 0.3334324169722621 0.6674084314089178" />
            </geometry>
        </collision>
    </link>
    <link name="Link5">
        <inertial>
            <origin xyz="-0.20763461922706636 0.0 0.0" rpy="0 0 0"/>
            <mass value="1.0" />
            <inertia ixx="100" ixy="0" ixz="0" iyy="100" iyz="0" izz="100" />
        </inertial>
        <visual>
            <origin xyz="-0.20763461922706636 0.0 0.0" rpy="0 0 0"/>
            <geometry>
                <box size="0.4152692384541327 0.4003040340923294 0.5621016917007684" />
            </geometry>
            <material name="Green">
            <color rgba="0.164 0.776 0.478 1.0"/>
            </material>
        </visual>
        <collision>
            <origin xyz="-0.20763461922706636 0.0 0.0" rpy="0 0 0"/>
            <geometry>
                <box size="0.4152692384541327 0.4003040340923294 0.5621016917007684" />
            </geometry>
        </collision>
    </link>
    <link name="Link6">
        <inertial>
            <origin xyz="0.0 0.0 0.2109797839561683" rpy="0 0 0"/>
            <mass value="1.0" />
            <inertia ixx="100" ixy="0" ixz="0" iyy="100" iyz="0" izz="100" />
        </inertial>
        <visual>
            <origin xyz="0.0 0.0 0.2109797839561683" rpy="0 0 0"/>
            <geometry>
                <box size="0.35397923451839075 0.3933297242399946 0.4219595679123366" />
            </geometry>
            <material name="Green">
            <color rgba="0.164 0.776 0.478 1.0"/>
            </material>
        </visual>
        <collision>
            <origin xyz="0.0 0.0 0.2109797839561683" rpy="0 0 0"/>
            <geometry>
                <box size="0.35397923451839075 0.3933297242399946 0.4219595679123366" />
            </geometry>
        </collision>
    </link>
    <link name="Link7">
        <inertial>
            <origin xyz="0.0 0.0 0.19199721605913936" rpy="0 0 0"/>
            <mass value="1.0" />
            <inertia ixx="100" ixy="0" ixz="0" iyy="100" iyz="0" izz="100" />
        </inertial>
        <visual>
            <origin xyz="0.0 0.0 0.19199721605913936" rpy="0 0 0"/>
            <geometry>
                <box size="0.3918785695296527 0.5718334313788048 0.3839944321182787" />
            </geometry>
            <material name="Green">
            <color rgba="0.164 0.776 0.478 1.0"/>
            </material>
        </visual>
        <collision>
            <origin xyz="0.0 0.0 0.19199721605913936" rpy="0 0 0"/>
            <geometry>
                <box size="0.3918785695296527 0.5718334313788048 0.3839944321182787" />
            </geometry>
        </collision>
    </link>
    <link name="Link8">
        <inertial>
            <origin xyz="-0.4101863047478772 0.0 0.0" rpy="0 0 0"/>
            <mass value="1.0" />
            <inertia ixx="100" ixy="0" ixz="0" iyy="100" iyz="0" izz="100" />
        </inertial>
        <visual>
            <origin xyz="-0.4101863047478772 0.0 0.0" rpy="0 0 0"/>
            <geometry>
                <box size="0.8203726094957544 0.40539634017671683 0.4488854194924229" />
            </geometry>
            <material name="Blue">
            <color rgba="0.164 0.776 0.95 1.0"/>
            </material>
        </visual>
        <collision>
            <origin xyz="-0.4101863047478772 0.0 0.0" rpy="0 0 0"/>
            <geometry>
                <box size="0.8203726094957544 0.40539634017671683 0.4488854194924229" />
            </geometry>
        </collision>
    </link>
    <joint name="Link0_Link1" type="revolute">
       <parent link="Link0"/>
       <child  link="Link1"/>
       <origin rpy="0 0 0" xyz="0.0 0.0 3.5" />
     <axis xyz="0 0 1"/>
       <limit effort="0.0" lower="-3.14159" upper="3.14159" velocity="0.0"/>
    </joint>
    <joint name="Link0_Link2" type="revolute">
       <parent link="Link0"/>
       <child  link="Link2"/>
       <origin rpy="0 0 0" xyz="0.0 0.5 3.0" />
     <axis xyz="1 0 0"/>
       <limit effort="0.0" lower="-3.14159" upper="3.14159" velocity="0.0"/>
    </joint>
    <joint name="Link2_Link3" type="revolute">
       <parent link="Link2"/>
       <child  link="Link3"/>
       <origin rpy="0 0 0" xyz="0.0 0.3923949376109851 0.4471468928703013" />
     <axis xyz="0 0 1"/>
       <limit effort="0.0" lower="-3.14159" upper="3.14159" velocity="0.0"/>
    </joint>
    <joint name="Link1_Link4" type="revolute">
       <parent link="Link1"/>
       <child  link="Link4"/>
       <origin rpy="0 0 0" xyz="0.49032381904307987 0.0 0.47256122808935475" />
     <axis xyz="0 1 0"/>
       <limit effort="0.0" lower="-3.14159" upper="3.14159" velocity="0.0"/>
    </joint>
    <joint name="Link3_Link5" type="revolute">
       <parent link="Link3"/>
       <child  link="Link5"/>
       <origin rpy="0 0 0" xyz="-0.23036583275997874 0.0 0.4044400912638708" />
     <axis xyz="0 0 1"/>
       <limit effort="0.0" lower="-3.14159" upper="3.14159" velocity="0.0"/>
    </joint>
    <joint name="Link5_Link6" type="revolute">
       <parent link="Link5"/>
       <child  link="Link6"/>
       <origin rpy="0 0 0" xyz="-0.20763461922706633 0.0 0.2810508458503844" />
     <axis xyz="0 0 1"/>
       <limit effort="0.0" lower="-3.14159" upper="3.14159" velocity="0.0"/>
    </joint>
    <joint name="Link3_Link7" type="revolute">
       <parent link="Link3"/>
       <child  link="Link7"/>
       <origin rpy="0 0 0" xyz="0.0 0.0 0.8088801825277416" />
     <axis xyz="0 1 0"/>
       <limit effort="0.0" lower="-3.14159" upper="3.14159" velocity="0.0"/>
    </joint>
    <joint name="Link1_Link8" type="revolute">
       <parent link="Link1"/>
       <child  link="Link8"/>
       <origin rpy="0 0 0" xyz="-0.49032381904307987 0.0 0.47256122808935475" />
     <axis xyz="1 0 0"/>
       <limit effort="0.0" lower="-3.14159" upper="3.14159" velocity="0.0"/>
    </joint>
</robot>