<robot name = "robot">
    <link name="Link0">
        <inertial>
            <origin xyz="0 0 3" rpy="0 0 0"/>
            <mass value="1.0" />
            <inertia ixx="100" ixy="0" ixz="0" iyy="100" iyz="0" izz="100" />
        </inertial>
        <visual>
            <origin xyz="0 0 3" rpy="0 0 0"/>
            <geometry>
                <box size="1 1 1" />
            </geometry>
            <material name="Blue">
            <color rgba="0.164 0.776 0.95 1.0"/>
            </material>
        </visual>
        <collision>
            <origin xyz="0 0 3" rpy="0 0 0"/>
            <geometry>
                <box size="1 1 1" />
            </geometry>
        </collision>
    </link>
    <link name="Link1">
        <inertial>
            <origin xyz="0.0 0.4274561319239226 0.0" rpy="0 0 0"/>
            <mass value="1.0" />
            <inertia ixx="100" ixy="0" ixz="0" iyy="100" iyz="0" izz="100" />
        </inertial>
        <visual>
            <origin xyz="0.0 0.4274561319239226 0.0" rpy="0 0 0"/>
            <geometry>
                <box size="0.4307689951487973 0.8549122638478452 0.7053046437013906" />
            </geometry>
            <material name="Green">
            <color rgba="0.164 0.776 0.478 1.0"/>
            </material>
        </visual>
        <collision>
            <origin xyz="0.0 0.4274561319239226 0.0" rpy="0 0 0"/>
            <geometry>
                <box size="0.4307689951487973 0.8549122638478452 0.7053046437013906" />
            </geometry>
        </collision>
    </link>
    <link name="Link2">
        <inertial>
            <origin xyz="-0.34047889496376443 0.0 0.0" rpy="0 0 0"/>
            <mass value="1.0" />
            <inertia ixx="100" ixy="0" ixz="0" iyy="100" iyz="0" izz="100" />
        </inertial>
        <visual>
            <origin xyz="-0.34047889496376443 0.0 0.0" rpy="0 0 0"/>
            <geometry>
                <box size="0.6809577899275289 0.7052898054219587 0.717173778000703" />
            </geometry>
            <material name="Green">
            <color rgba="0.164 0.776 0.478 1.0"/>
            </material>
        </visual>
        <collision>
            <origin xyz="-0.34047889496376443 0.0 0.0" rpy="0 0 0"/>
            <geometry>
                <box size="0.6809577899275289 0.7052898054219587 0.717173778000703" />
            </geometry>
        </collision>
    </link>
    <link name="Link3">
        <inertial>
            <origin xyz="0.0 0.0 -0.4536446178318614" rpy="0 0 0"/>
            <mass value="1.0" />
            <inertia ixx="100" ixy="0" ixz="0" iyy="100" iyz="0" izz="100" />
        </inertial>
        <visual>
            <origin xyz="0.0 0.0 -0.4536446178318614" rpy="0 0 0"/>
            <geometry>
                <box size="0.5812415581243431 0.4876446722883233 0.9072892356637228" />
            </geometry>
            <material name="Green">
            <color rgba="0.164 0.776 0.478 1.0"/>
            </material>
        </visual>
        <collision>
            <origin xyz="0.0 0.0 -0.4536446178318614" rpy="0 0 0"/>
            <geometry>
                <box size="0.5812415581243431 0.4876446722883233 0.9072892356637228" />
            </geometry>
        </collision>
    </link>
    <link name="Link4">
        <inertial>
            <origin xyz="0.0 0.0 0.30801682064198976" rpy="0 0 0"/>
            <mass value="1.0" />
            <inertia ixx="100" ixy="0" ixz="0" iyy="100" iyz="0" izz="100" />
        </inertial>
        <visual>
            <origin xyz="0.0 0.0 0.30801682064198976" rpy="0 0 0"/>
            <geometry>
                <box size="0.37133356641462306 0.7009954440344491 0.6160336412839795" />
            </geometry>
            <material name="Green">
            <color rgba="0.164 0.776 0.478 1.0"/>
            </material>
        </visual>
        <collision>
            <origin xyz="0.0 0.0 0.30801682064198976" rpy="0 0 0"/>
            <geometry>
                <box size="0.37133356641462306 0.7009954440344491 0.6160336412839795" />
            </geometry>
        </collision>
    </link>
    <joint name="Link0_Link1" type="revolute">
       <parent link="Link0"/>
       <child  link="Link1"/>
       <origin rpy="0 0 0" xyz="0.0 0.5 3.0" />
     <axis xyz="0 1 0"/>
       <limit effort="0.0" lower="-3.14159" upper="3.14159" velocity="0.0"/>
    </joint>
    <joint name="Link0_Link2" type="revolute">
       <parent link="Link0"/>
       <child  link="Link2"/>
       <origin rpy="0 0 0" xyz="-0.5 0.0 3.0" />
     <axis xyz="1 0 0"/>
       <limit effort="0.0" lower="-3.14159" upper="3.14159" velocity="0.0"/>
    </joint>
    <joint name="Link0_Link3" type="revolute">
       <parent link="Link0"/>
       <child  link="Link3"/>
       <origin rpy="0 0 0" xyz="0.0 0.0 2.5" />
     <axis xyz="0 1 0"/>
       <limit effort="0.0" lower="-3.14159" upper="3.14159" velocity="0.0"/>
    </joint>
    <joint name="Link1_Link4" type="revolute">
       <parent link="Link1"/>
       <child  link="Link4"/>
       <origin rpy="0 0 0" xyz="0.0 0.4274561319239226 0.3526523218506954" />
     <axis xyz="0 1 0"/>
       <limit effort="0.0" lower="-3.14159" upper="3.14159" velocity="0.0"/>
    </joint>
</robot>